Workbook

Sheet LISTAS
B2: Estado | D2: Broker | E2: Plazo_max_horas | G2: Doctor | H2: Correo | J2: Plazo | L2: DIAS_NO_LABORABLES
B3: FINALIZADO | D3: ARTHUR GALLAGHER | E3: 6 | G3: DR PEREZ | H3: jlperez@mapfre.com.pe | J3: Dentro | L3: {=_xlfn.LET(_xlpm.y,YEAR(TODAY()),_xlpm.i,_xlfn.SEQUENCE(64),_xlpm.a,_xlpm.y-INT((_xlpm.i-1)/16),_xlpm.h,MOD(_xlpm.i-1,16)+1,_xlpm.pas,ROUND(DATE(_xlpm.a,4,1)/7+MOD(19*MOD(_xlpm.a,19)-7,30)*0.14,0)*7-6,_xlpm.m,CHOOSE(_xlpm.h,1,1,1,5,6,6,7,7,7,8,8,10,11,12,12,12),_xlpm.d,CHOOSE(_xlpm.h,1,1,1,1,7,29,23,28,29,6,30,8,1,8,9,25),IF(_xlpm.h=2,_xlpm.pas-3,IF(_xlpm.h=3,_xlpm.pas-2,DATE(_xlpm.a,_xlpm.m,_xlpm.d))))} -> 46023 | M3: <-- Automático: feriados de Perú del año actual y los 3 anteriores (64 fechas). No escribir aquí abajo. Para más años, en L3 cambiar SECUENCIA(64) por 80, 96, etc. (16 por año).
B4: SOLICITA INFORMACIÓN | D4: GABEL | E4: <-- E3 es el plazo en horas. Cambia ese número si cambia el SeviceLevelAgreement. | G4: DRA ANA | H4: anavf2110@gmail.com | J4: Fuera | L4: 46114
B5: INFORMACIÓN ENVIADA | D5: HOWDEN | L5: 46115
D6: MARSH | L6: 46143
B7: (en blanco = PENDIENTE) | D7: UIB | L7: 46180
L8: 46202
L9: 46226
L10: 46231
L11: 46232
L12: 46240
L13: 46264
L14: 46303
L15: 46327
L16: 46364
L17: 46365
L18: 46381
L19: 45658
... L66: 45285

Sheet INDICADORES
B2: INDICADORES BROKERS
B4: CORREOS POR BROKER
B5: ARTHUR GALLAGHER | C5: =COUNTIF(SCTR_Brokers[Broker],"ARTHUR GALLAGHER") -> 102
B6: GABEL | C6: =COUNTIF(SCTR_Brokers[Broker],"GABEL") -> 53
B7: HOWDEN | C7: =COUNTIF(SCTR_Brokers[Broker],"HOWDEN") -> 73
B8: MARSH | C8: =COUNTIF(SCTR_Brokers[Broker],"MARSH") -> 250
B9: UIB | C9: =COUNTIF(SCTR_Brokers[Broker],"UIB") -> 51
B10: TOTAL | C10: =COUNTA(SCTR_Brokers[ConversationId]) -> 531
B12: ESTADO
B13: PENDIENTE (en blanco) | C13: =COUNTA(SCTR_Brokers[ConversationId])-COUNTIF(SCTR_Brokers[Estado],"FINALIZADO")-COUNTIF(SCTR_Brokers[Estado],"SOLICITA INFORMACIÓN")-COUNTIF(SCTR_Brokers[Estado],"INFORMACIÓN ENVIADA") -> 18
B14: SOLICITA INFORMACIÓN | C14: =COUNTIF(SCTR_Brokers[Estado],"SOLICITA INFORMACIÓN") -> 1
B15: INFORMACIÓN ENVIADA | C15: =COUNTIF(SCTR_Brokers[Estado],"INFORMACIÓN ENVIADA") -> 1
B16: FINALIZADO | C16: =COUNTIF(SCTR_Brokers[Estado],"FINALIZADO") -> 511
B19: ="PLAZO ("&LISTAS!E3&" h)" -> PLAZO (6 h)
B20: Finalizados DENTRO | C20: =SUM(SCTR_Brokers[DentroPlazo_Finalizado]) -> 379
B21: Finalizados FUERA | C21: =SUM(SCTR_Brokers[FueraPlazo_Finalizado]) -> 132
B22: Pendientes FUERA | C22: =SUM(SCTR_Brokers[PendienteFueraPlazo]) -> 5
B23: % cumplimiento | C23: =IFERROR(SUM(SCTR_Brokers[DentroPlazo_Finalizado])/SUM(SCTR_Brokers[EsFinalizado]),"") -> 0.74168297
B26: ÁREA MÉDICA
B27: Solicitudes al doctor | C27: =SUM(SCTR_Brokers[SolicitoInforme]) -> 36
B28: Informes recibidos | C28: =SUM(SCTR_Brokers[InformeRecibido]) -> 24
B29: Pendientes de doctor | C29: =SUM(SCTR_Brokers[PendienteDoctor]) -> 14
B30: Horas prom. respuesta | C30: =IFERROR(AVERAGE(SCTR_Brokers[HorasRespuestaDoctor]),"") -> 3.6863636

Sheet SEGUIMIENTO
A1: ConversationId | B1: ConversationId_Alt | C1: CasoId | D1: Asunto | E1: Broker | F1: FechaRecepcion | G1: FechaUltimaRespuesta | H1: PersonaUltimaRespuesta | I1: Estado | J1: Observaciones | K1: Encargado | L1: CorreoDoctor | M1: DoctorEncargado | N1: Horas_Transcurridas | O1: Fecha_Solic_Informe | P1: Fecha_Informe | Q1: Fecha_Cierre | R1: Plazo | S1: Derivado | T1: Mes | U1: EsFinalizado | V1: EsPendiente | W1: DentroPlazo_Finalizado | X1: FueraPlazo_Finalizado | Y1: PendienteFueraPlazo | Z1: SolicitoInforme | AA1: InformeRecibido | AB1: PendienteDoctor | AC1: HorasRespuestaDoctor
A2: AAQkADdkNThjNzFkLWM0ZmMtNDJhYS04MDVlLTIwNzE4ZDI1Mzg4YgAQAJce04pfmOxCjc66JQ_YqAI= | C2: =IF(SCTR_Brokers[[#This Row],[FechaRecepcion]]="","",SCTR_Brokers[[#This Row],[ConversationId]]&"-"&TEXT(SCTR_Brokers[[#This Row],[FechaRecepcion]],"aaaammddhhmmss")) -> AAQkADdkNThjNzFkLWM0ZmMtNDJhYS04MDVlLTIwNzE4ZDI1Mzg4YgAQAJce04pfmOxCjc66JQ_YqAI=-20260813130900 | D2: RE: TAMSHI: ACCIDENTE LABORAL_REATEGUI CURICHIMBA MARCOS (mordedura de serpiente) | E2: MARSH | F2: 46247.548 | G2: 46247.617 | H2: Katherine.Andrade@marsh.com | I2: FINALIZADO | K2: SCTR SALUD | N2: =IF(SCTR_Brokers[[#This Row],[FechaRecepcion]]="","",IF(SCTR_Brokers[[#This Row],[Estado]]="FINALIZADO","",IF(SCTR_Brokers[[#This Row],[FechaUltimaRespuesta]]="","",_xlfn.LET(_xlpm.fer,LISTAS!$L$3:$L$100,_xlpm.ep,DATE(2000,1,1),_xlpm.ini,SCTR_Brokers[[#This Row],[FechaUltimaRespuesta]],_xlpm.fin,NOW(),_xlpm.dini,INT(_xlpm.ini),_xlpm.dfin,INT(_xlpm.fin),_xlpm.hini,9.5*NETWORKDAYS.INTL(_xlpm.ep,_xlpm.dini-1,"0000111",_xlpm.fer)+6*NETWORKDAYS.INTL(_xlpm.ep,_xlpm.dini-1,"1111011",_xlpm.fer)+IF(OR(WEEKDAY(_xlpm.dini,2)>5,COUNTIF(_xlpm.fer,_xlpm.dini)>0),0,MAX(0,MIN(_xlpm.ini-_xlpm.dini,IF(WEEKDAY(_xlpm.dini,2)=5,14/24,17.5/24))-8/24)*24),_xlpm.hfin,9.5*NETWORKDAYS.INTL(_xlpm.ep,_xlpm.dfin-1,"0000111",_xlpm.fer)+6*NETWORKDAYS.INTL(_xlpm.ep,_xlpm.dfin-1,"1111011",_xlpm.fer)+IF(OR(WEEKDAY(_xlpm.dfin,2)>5,COUNTIF(_xlpm.fer,_xlpm.dfin)>0),0,MAX(0,MIN(_xlpm.fin-_xlpm.dfin,IF(WEEKDAY(_xlpm.dfin,2)=5,14/24,17.5/24))-8/24)*24),ROUND(MAX(0,_xlpm.hfin-_xlpm.hini),1))))) | Q2: 46247.618 | R2: =IF(SCTR_Brokers[[#This Row],[FechaRecepcion]]="","",_xlfn.LET(_xlpm.fer,LISTAS!$L$3:$L$100,_xlpm.ep,DATE(2000,1,1),_xlpm.ini,SCTR_Brokers[[#This Row],[FechaRecepcion]],_xlpm.fin,IF(SCTR_Brokers[[#This Row],[Fecha_Cierre]]<>"",SCTR_Brokers[[#This Row],[Fecha_Cierre]],NOW()),_xlpm.dini,INT(_xlpm.ini),_xlpm.dfin,INT(_xlpm.fin),_xlpm.hini,9.5*NETWORKDAYS.INTL(_xlpm.ep,_xlpm.dini-1,"0000111",_xlpm.fer)+6*NETWORKDAYS.INTL(_xlpm.ep,_xlpm.dini-1,"1111011",_xlpm.fer)+IF(OR(WEEKDAY(_xlpm.dini,2)>5,COUNTIF(_xlpm.fer,_xlpm.dini)>0),0,MAX(0,MIN(_xlpm.ini-_xlpm.dini,IF(WEEKDAY(_xlpm.dini,2)=5,14/24,17.5/24))-8/24)*24),_xlpm.hfin,9.5*NETWORKDAYS.INTL(_xlpm.ep,_xlpm.dfin-1,"0000111",_xlpm.fer)+6*NETWORKDAYS.INTL(_xlpm.ep,_xlpm.dfin-1,"1111011",_xlpm.fer)+IF(OR(WEEKDAY(_xlpm.dfin,2)>5,COUNTIF(_xlpm.fer,_xlpm.dfin)>0),0,MAX(0,MIN(_xlpm.fin-_xlpm.dfin,IF(WEEKDAY(_xlpm.dfin,2)=5,14/24,17.5/24))-8/24)*24),_xlpm.hrs,IF(SCTR_Brokers[[#This Row],[Estado]]="FINALIZADO",MAX(0,_xlpm.hfin-_xlpm.hini),IF(SCTR_Brokers[[#This Row],[Horas_Transcurridas]]="",MAX(0,_xlpm.hfin-_xlpm.hini),SCTR_Brokers[[#This Row],[Horas_Transcurridas]])),IF(_xlpm.hrs<=LISTAS!$E$3,LISTAS!$J$3,LISTAS!$J$4))) -> Dentro | T2: =IF(SCTR_Brokers[[#This Row],[FechaRecepcion]]="","",TEXT(SCTR_Brokers[[#This Row],[FechaRecepcion]],"mmmm")&" "&YEAR(SCTR_Brokers[[#This Row],[FechaRecepcion]])) -> agosto 2026 | U2: =IF(SCTR_Brokers[[#This Row],[Estado]]="FINALIZADO",1,0) -> 1 | V2: =IF(SCTR_Brokers[[#This Row],[FechaRecepcion]]="","",IF(SCTR_Brokers[[#This Row],[Estado]]="FINALIZADO",0,1)) -> 0 | W2: =IF(AND(SCTR_Brokers[[#This Row],[Estado]]="FINALIZADO",SCTR_Brokers[[#This Row],[Plazo]]=LISTAS!$J$3),1,0) -> 1 | X2: =IF(AND(SCTR_Brokers[[#This Row],[Estado]]="FINALIZADO",SCTR_Brokers[[#This Row],[Plazo]]=LISTAS!$J$4),1,0) -> 0 | Y2: =IF(AND(SCTR_Brokers[[#This Row],[Estado]]<>"FINALIZADO",SCTR_Brokers[[#This Row],[Plazo]]=LISTAS!$J$4),1,0) -> 0 | Z2: =IF(SCTR_Brokers[[#This Row],[Fecha_Solic_Informe]]="",0,1) -> 0 | AA2: =IF(SCTR_Brokers[[#This Row],[Fecha_Informe]]="",0,1) -> 0 | AB2: =IF(AND(SCTR_Brokers[[#This Row],[Fecha_Solic_Informe]]<>"",SCTR_Brokers[[#This Row],[Fecha_Informe]]=""),1,0) -> 0 | AC2: =IF(AND(SCTR_Brokers[[#This Row],[Fecha_Solic_Informe]]<>"",SCTR_Brokers[[#This Row],[Fecha_Informe]]<>""),ROUND((SCTR_Brokers[[#This Row],[Fecha_Informe]]-SCTR_Brokers[[#This Row],[Fecha_Solic_Informe]])*24,1),"")
A3: AAQkADdkNThjNzFkLWM0ZmMtNDJhYS04MDVlLTIwNzE4ZDI1Mzg4YgAQAH-nDgfBdEb_vQ6M26ET90Q= | C3: =IF(SCTR_Brokers[[#This Row],[FechaRecepcion]]="","",SCTR_Brokers[[#This Row],[ConversationId]]&"-"&TEXT(SCTR_Brokers[[#This Row],[FechaRecepcion]],"aaaammddhhmmss")) -> AAQkADdkNThjNzFkLWM0ZmMtNDJhYS04MDVlLTIwNzE4ZDI1Mzg4YgAQAH-nDgfBdEb_vQ6M26ET90Q=-20260813150331 | D3: MOTIVO DEL RECHAZO DE CG _ DNI 10615639 _ PAREDES CANDELA DANIEL WALTER _REPRESENTACIONES YAGO SAC _ RUC 20505006675 _ SCTR | E3: GABEL | F3: 46247.627 | G3: 46247.694 | H3: sctrsalud@mapfre.com.pe | I3: FINALIZADO | K3: SCTR SALUD | N3: =IF(SCTR_Brokers[[#This Row],[FechaRecepcion]]="","",IF(SCTR_Brokers[[#This Row],[Estado]]="FINALIZADO","",IF(SCTR_Brokers[[#This Row],[FechaUltimaRespuesta]]="","",_xlfn.LET(_xlpm.fer,LISTAS!$L$3:$L$100,_xlpm.ep,DATE(2000,1,1),_xlpm.ini,SCTR_Brokers[[#This Row],[FechaUltimaRespuesta]],_xlpm.fin,NOW(),_xlpm.dini,INT(_xlpm.ini),_xlpm.dfin,INT(_xlpm.fin),_xlpm.hini,9.5*NETWORKDAYS.INTL(_xlpm.ep,_xlpm.dini-1,"0000111",_xlpm.fer)+6*NETWORKDAYS.INTL(_xlpm.ep,_xlpm.dini-1,"1111011",_xlpm.fer)+IF(OR(WEEKDAY(_xlpm.dini,2)>5,COUNTIF(_xlpm.fer,_xlpm.dini)>0),0,MAX(0,MIN(_xlpm.ini-_xlpm.dini,IF(WEEKDAY(_xlpm.dini,2)=5,14/24,17.5/24))-8/24)*24),_xlpm.hfin,9.5*NETWORKDAYS.INTL(_xlpm.ep,_xlpm.dfin-1,"0000111",_xlpm.fer)+6*NETWORKDAYS.INTL(_xlpm.ep,_xlpm.dfin-1,"1111011",_xlpm.fer)+IF(OR(WEEKDAY(_xlpm.dfin,2)>5,COUNTIF(_xlpm.fer,_xlpm.dfin)>0),0,MAX(0,MIN(_xlpm.fin-_xlpm.dfin,IF(WEEKDAY(_xlpm.dfin,2)=5,14/24,17.5/24))-8/24)*24),ROUND(MAX(0,_xlpm.hfin-_xlpm.hini),1))))) | Q3: 46247.694 | R3: =IF(SCTR_Brokers[[#This Row],[FechaRecepcion]]="","",_xlfn.LET(_xlpm.fer,LISTAS!$L$3:$L$100,_xlpm.ep,DATE(2000,1,1),_xlpm.ini,SCTR_Brokers[[#This Row],[FechaRecepcion]],_xlpm.fin,IF(SCTR_Brokers[[#This Row],[Fecha_Cierre]]<>"",SCTR_Brokers[[#This Row],[Fecha_Cierre]],NOW()),_xlpm.dini,INT(_xlpm.ini),_xlpm.dfin,INT(_xlpm.fin),_xlpm.hini,9.5*NETWORKDAYS.INTL(_xlpm.ep,_xlpm.dini-1,"0000111",_xlpm.fer)+6*NETWORKDAYS.INTL(_xlpm.ep,_xlpm.dini-1,"1111011",_xlpm.fer)+IF(OR(WEEKDAY(_xlpm.dini,2)>5,COUNTIF(_xlpm.fer,_xlpm.dini)>0),0,MAX(0,MIN(_xlpm.ini-_xlpm.dini,IF(WEEKDAY(_xlpm.dini,2)=5,14/24,17.5/24))-8/24)*24),_xlpm.hfin,9.5*NETWORKDAYS.INTL(_xlpm.ep,_xlpm.dfin-1,"0000111",_xlpm.fer)+6*NETWORKDAYS.INTL(_xlpm.ep,_xlpm.dfin-1,"1111011",_xlpm.fer)+IF(OR(WEEKDAY(_xlpm.dfin,2)>5,COUNTIF(_xlpm.fer,_xlpm.dfin)>0),0,MAX(0,MIN(_xlpm.fin-_xlpm.dfin,IF(WEEKDAY(_xlpm.dfin,2)=5,14/24,17.5/24))-8/24)*24),_xlpm.hrs,IF(SCTR_Brokers[[#This Row],[Estado]]="FINALIZADO",MAX(0,_xlpm.hfin-_xlpm.hini),IF(SCTR_Brokers[[#This Row],[Horas_Transcurridas]]="",MAX(0,_xlpm.hfin-_xlpm.hini),SCTR_Brokers[[#This Row],[Horas_Transcurridas]])),IF(_xlpm.hrs<=LISTAS!$E$3,LISTAS!$J$3,LISTAS!$J$4))) -> Dentro | T3: =IF(SCTR_Brokers[[#This Row],[FechaRecepcion]]="","",TEXT(SCTR_Brokers[[#This Row],[FechaRecepcion]],"mmmm")&" "&YEAR(SCTR_Brokers[[#This Row],[FechaRecepcion]])) -> agosto 2026 | U3: =IF(SCTR_Brokers[[#This Row],[Estado]]="FINALIZADO",1,0) -> 1 | V3: =IF(SCTR_Brokers[[#This Row],[FechaRecepcion]]="","",IF(SCTR_Brokers[[#This Row],[Estado]]="FINALIZADO",0,1)) -> 0 | W3: =IF(AND(SCTR_Brokers[[#This Row],[Estado]]="FINALIZADO",SCTR_Brokers[[#This Row],[Plazo]]=LISTAS!$J$3),1,0) -> 1 | X3: =IF(AND(SCTR_Brokers[[#This Row],[Estado]]="FINALIZADO",SCTR_Brokers[[#This Row],[Plazo]]=LISTAS!$J$4),1,0) -> 0 | Y3: =IF(AND(SCTR_Brokers[[#This Row],[Estado]]<>"FINALIZADO",SCTR_Brokers[[#This Row],[Plazo]]=LISTAS!$J$4),1,0) -> 0 | Z3: =IF(SCTR_Brokers[[#This Row],[Fecha_Solic_Informe]]="",0,1) -> 0 | AA3: =IF(SCTR_Brokers[[#This Row],[Fecha_Informe]]="",0,1) -> 0 | AB3: =IF(AND(SCTR_Brokers[[#This Row],[Fecha_Solic_Informe]]<>"",SCTR_Brokers[[#This Row],[Fecha_Informe]]=""),1,0) -> 0 | AC3: =IF(AND(SCTR_Brokers[[#This Row],[Fecha_Solic_Informe]]<>"",SCTR_Brokers[[#This Row],[Fecha_Informe]]<>""),ROUND((SCTR_Brokers[[#This Row],[Fecha_Informe]]-SCTR_Brokers[[#This Row],[Fecha_Solic_Informe]])*24,1),"")
A4: AAQkADdkNThjNzFkLWM0ZmMtNDJhYS04MDVlLTIwNzE4ZDI1Mzg4YgAQAJt1sQcA00SYr0ix69nzDCs= | C4: =IF(SCTR_Brokers[[#This Row],[FechaRecepcion]]="","",SCTR_Brokers[[#This Row],[ConversationId]]&"-"&TEXT(SCTR_Brokers[[#This Row],[FechaRecepcion]],"aaaammddhhmmss")) -> AAQkADdkNThjNzFkLWM0ZmMtNDJhYS04MDVlLTIwNzE4ZDI1Mzg4YgAQAJt1sQcA00SYr0ix69nzDCs=-20260813152212 | D4: DERIVACION PROVEEDOR ECOGRAFIA CODO - CONTRATISTAS MINEROS ALFA - SCTR SALUD | E4: ARTHUR GALLAGHER | F4: 46247.64 | G4: 46251.334 | H4: Jackeline_Murayari@ajg.com | I4: FINALIZADO | K4: SCTR SALUD | N4: =IF(SCTR_Brokers[[#This Row],[FechaRecepcion]]="","",IF(SCTR_Brokers[[#This Row],[Estado]]="FINALIZADO","",IF(SCTR_Brokers[[#This Row],[FechaUltimaRespuesta]]="","",_xlfn.LET(_xlpm.fer,LISTAS!$L$3:$L$100,_xlpm.ep,DATE(2000,1,1),_xlpm.ini,SCTR_Brokers[[#This Row],[FechaUltimaRespuesta]],_xlpm.fin,NOW(),_xlpm.dini,INT(_xlpm.ini),_xlpm.dfin,INT(_xlpm.fin),_xlpm.hini,9.5*NETWORKDAYS.INTL(_xlpm.ep,_xlpm.dini-1,"0000111",_xlpm.fer)+6*NETWORKDAYS.INTL(_xlpm.ep,_xlpm.dini-1,"1111011",_xlpm.fer)+IF(OR(WEEKDAY(_xlpm.dini,2)>5,COUNTIF(_xlpm.fer,_xlpm.dini)>0),0,MAX(0,MIN(_xlpm.ini-_xlpm.dini,IF(WEEKDAY(_xlpm.dini,2)=5,14/24,17.5/24))-8/24)*24),_xlpm.hfin,9.5*NETWORKDAYS.INTL(_xlpm.ep,_xlpm.dfin-1,"0000111",_xlpm.fer)+6*NETWORKDAYS.INTL(_xlpm.ep,_xlpm.dfin-1,"1111011",_xlpm.fer)+IF(OR(WEEKDAY(_xlpm.dfin,2)>5,COUNTIF(_xlpm.fer,_xlpm.dfin)>0),0,MAX(0,MIN(_xlpm.fin-_xlpm.dfin,IF(WEEKDAY(_xlpm.dfin,2)=5,14/24,17.5/24))-8/24)*24),ROUND(MAX(0,_xlpm.hfin-_xlpm.hini),1))))) | Q4: 46251.334 | R4: =IF(SCTR_Brokers[[#This Row],[FechaRecepcion]]="","",_xlfn.LET(_xlpm.fer,LISTAS!$L$3:$L$100,_xlpm.ep,DATE(2000,1,1),_xlpm.ini,SCTR_Brokers[[#This Row],[FechaRecepcion]],_xlpm.fin,IF(SCTR_Brokers[[#This Row],[Fecha_Cierre]]<>"",SCTR_Brokers[[#This Row],[Fecha_Cierre]],NOW()),_xlpm.dini,INT(_xlpm.ini),_xlpm.dfin,INT(_xlpm.fin),_xlpm.hini,9.5*NETWORKDAYS.INTL(_xlpm.ep,_xlpm.dini-1,"0000111",_xlpm.fer)+6*NETWORKDAYS.INTL(_xlpm.ep,_xlpm.dini-1,"1111011",_xlpm.fer)+IF(OR(WEEKDAY(_xlpm.dini,2)>5,COUNTIF(_xlpm.fer,_xlpm.dini)>0),0,MAX(0,MIN(_xlpm.ini-_xlpm.dini,IF(WEEKDAY(_xlpm.dini,2)=5,14/24,17.5/24))-8/24)*24),_xlpm.hfin,9.5*NETWORKDAYS.INTL(_xlpm.ep,_xlpm.dfin-1,"0000111",_xlpm.fer)+6*NETWORKDAYS.INTL(_xlpm.ep,_xlpm.dfin-1,"1111011",_xlpm.fer)+IF(OR(WEEKDAY(_xlpm.dfin,2)>5,COUNTIF(_xlpm.fer,_xlpm.dfin)>0),0,MAX(0,MIN(_xlpm.fin-_xlpm.dfin,IF(WEEKDAY(_xlpm.dfin,2)=5,14/24,17.5/24))-8/24)*24),_xlpm.hrs,IF(SCTR_Brokers[[#This Row],[Estado]]="FINALIZADO",MAX(0,_xlpm.hfin-_xlpm.hini),IF(SCTR_Brokers[[#This Row],[Horas_Transcurridas]]="",MAX(0,_xlpm.hfin-_xlpm.hini),SCTR_Brokers[[#This Row],[Horas_Transcurridas]])),IF(_xlpm.hrs<=LISTAS!$E$3,LISTAS!$J$3,LISTAS!$J$4))) -> Fuera | T4: =IF(SCTR_Brokers[[#This Row],[FechaRecepcion]]="","",TEXT(SCTR_Brokers[[#This Row],[FechaRecepcion]],"mmmm")&" "&YEAR(SCTR_Brokers[[#This Row],[FechaRecepcion]])) -> agosto 2026 | U4: =IF(SCTR_Brokers[[#This Row],[Estado]]="FINALIZADO",1,0) -> 1 | V4: =IF(SCTR_Brokers[[#This Row],[FechaRecepcion]]="","",IF(SCTR_Brokers[[#This Row],[Estado]]="FINALIZADO",0,1)) -> 0 | W4: =IF(AND(SCTR_Brokers[[#This Row],[Estado]]="FINALIZADO",SCTR_Brokers[[#This Row],[Plazo]]=LISTAS!$J$3),1,0) -> 0 | X4: =IF(AND(SCTR_Brokers[[#This Row],[Estado]]="FINALIZADO",SCTR_Brokers[[#This Row],[Plazo]]=LISTAS!$J$4),1,0) -> 1 | Y4: =IF(AND(SCTR_Brokers[[#This Row],[Estado]]<>"FINALIZADO",SCTR_Brokers[[#This Row],[Plazo]]=LISTAS!$J$4),1,0) -> 0 | Z4: =IF(SCTR_Brokers[[#This Row],[Fecha_Solic_Informe]]="",0,1) -> 0 | AA4: =IF(SCTR_Brokers[[#This Row],[Fecha_Informe]]="",0,1) -> 0 | AB4: =IF(AND(SCTR_Brokers[[#This Row],[Fecha_Solic_Informe]]<>"",SCTR_Brokers[[#This Row],[Fecha_Informe]]=""),1,0) -> 0 | AC4: =IF(AND(SCTR_Brokers[[#This Row],[Fecha_Solic_Informe]]<>"",SCTR_Brokers[[#This Row],[Fecha_Informe]]<>""),ROUND((SCTR_Brokers[[#This Row],[Fecha_Informe]]-SCTR_Brokers[[#This Row],[Fecha_Solic_Informe]])*24,1),"")
A5: AAQkADdkNThjNzFkLWM0ZmMtNDJhYS04MDVlLTIwNzE4ZDI1Mzg4YgAQAO6d2gmjtd5Kpw0zInaJXh8= | C5: =IF(SCTR_Brokers[[#This Row],[FechaRecepcion]]="","",SCTR_Brokers[[#This Row],[ConversationId]]&"-"&TEXT(SCTR_Brokers[[#This Row],[FechaRecepcion]],"aaaammddhhmmss")) -> AAQkADdkNThjNzFkLWM0ZmMtNDJhYS04MDVlLTIwNzE4ZDI1Mzg4YgAQAO6d2gmjtd5Kpw0zInaJXh8=-20260813160806 | D5: Re: GRUPO INTERCORP // HOMECENTER // SOLICITUD DE FERULA - ACCIDENTE DE TRABAJO | E5: MARSH | F5: 46247.672 | G5: 46247.706 | H5: sctrsalud@mapfre.com.pe | I5: FINALIZADO | K5: SCTR SALUD | N5: =IF(SCTR_Brokers[[#This Row],[FechaRecepcion]]="","",IF(SCTR_Brokers[[#This Row],[Estado]]="FINALIZADO","",IF(SCTR_Brokers[[#This Row],[FechaUltimaRespuesta]]="","",_xlfn.LET(_xlpm.fer,LISTAS!$L$3:$L$100,_xlpm.ep,DATE(2000,1,1),_xlpm.ini,SCTR_Brokers[[#This Row],[FechaUltimaRespuesta]],_xlpm.fin,NOW(),_xlpm.dini,INT(_xlpm.ini),_xlpm.dfin,INT(_xlpm.fin),_xlpm.hini,9.5*NETWORKDAYS.INTL(_xlpm.ep,_xlpm.dini-1,"0000111",_xlpm.fer)+6*NETWORKDAYS.INTL(_xlpm.ep,_xlpm.dini-1,"1111011",_xlpm.fer)+IF(OR(WEEKDAY(_xlpm.dini,2)>5,COUNTIF(_xlpm.fer,_xlpm.dini)>0),0,MAX(0,MIN(_xlpm.ini-_xlpm.dini,IF(WEEKDAY(_xlpm.dini,2)=5,14/24,17.5/24))-8/24)*24),_xlpm.hfin,9.5*NETWORKDAYS.INTL(_xlpm.ep,_xlpm.dfin-1,"0000111",_xlpm.fer)+6*NETWORKDAYS.INTL(_xlpm.ep,_xlpm.dfin-1,"1111011",_xlpm.fer)+IF(OR(WEEKDAY(_xlpm.dfin,2)>5,COUNTIF(_xlpm.fer,_xlpm.dfin)>0),0,MAX(0,MIN(_xlpm.fin-_xlpm.dfin,IF(WEEKDAY(_xlpm.dfin,2)=5,14/24,17.5/24))-8/24)*24),ROUND(MAX(0,_xlpm.hfin-_xlpm.hini),1))))) | Q5: 46247.706 | R5: =IF(SCTR_Brokers[[#This Row],[FechaRecepcion]]="","",_xlfn.LET(_xlpm.fer,LISTAS!$L$3:$L$100,_xlpm.ep,DATE(2000,1,1),_xlpm.ini,SCTR_Brokers[[#This Row],[FechaRecepcion]],_xlpm.fin,IF(SCTR_Brokers[[#This Row],[Fecha_Cierre]]<>"",SCTR_Brokers[[#This Row],[Fecha_Cierre]],NOW()),_xlpm.dini,INT(_xlpm.ini),_xlpm.dfin,INT(_xlpm.fin),_xlpm.hini,9.5*NETWORKDAYS.INTL(_xlpm.ep,_xlpm.dini-1,"0000111",_xlpm.fer)+6*NETWORKDAYS.INTL(_xlpm.ep,_xlpm.dini-1,"1111011",_xlpm.fer)+IF(OR(WEEKDAY(_xlpm.dini,2)>5,COUNTIF(_xlpm.fer,_xlpm.dini)>0),0,MAX(0,MIN(_xlpm.ini-_xlpm.dini,IF(WEEKDAY(_xlpm.dini,2)=5,14/24,17.5/24))-8/24)*24),_xlpm.hfin,9.5*NETWORKDAYS.INTL(_xlpm.ep,_xlpm.dfin-1,"0000111",_xlpm.fer)+6*NETWORKDAYS.INTL(_xlpm.ep,_xlpm.dfin-1,"1111011",_xlpm.fer)+IF(OR(WEEKDAY(_xlpm.dfin,2)>5,COUNTIF(_xlpm.fer,_xlpm.dfin)>0),0,MAX(0,MIN(_xlpm.fin-_xlpm.dfin,IF(WEEKDAY(_xlpm.dfin,2)=5,14/24,17.5/24))-8/24)*24),_xlpm.hrs,IF(SCTR_Brokers[[#This Row],[Estado]]="FINALIZADO",MAX(0,_xlpm.hfin-_xlpm.hini),IF(SCTR_Brokers[[#This Row],[Horas_Transcurridas]]="",MAX(0,_xlpm.hfin-_xlpm.hini),SCTR_Brokers[[#This Row],[Horas_Transcurridas]])),IF(_xlpm.hrs<=LISTAS!$E$3,LISTAS!$J$3,LISTAS!$J$4))) -> Dentro | T5: =IF(SCTR_Brokers[[#This Row],[FechaRecepcion]]="","",TEXT(SCTR_Brokers[[#This Row],[FechaRecepcion]],"mmmm")&" "&YEAR(SCTR_Brokers[[#This Row],[FechaRecepcion]])) -> agosto 2026 | U5: =IF(SCTR_Brokers[[#This Row],[Estado]]="FINALIZADO",1,0) -> 1 | V5: =IF(SCTR_Brokers[[#This Row],[FechaRecepcion]]="","",IF(SCTR_Brokers[[#This Row],[Estado]]="FINALIZADO",0,1)) -> 0 | W5: =IF(AND(SCTR_Brokers[[#This Row],[Estado]]="FINALIZADO",SCTR_Brokers[[#This Row],[Plazo]]=LISTAS!$J$3),1,0) -> 1 | X5: =IF(AND(SCTR_Brokers[[#This Row],[Estado]]="FINALIZADO",SCTR_Brokers[[#This Row],[Plazo]]=LISTAS!$J$4),1,0) -> 0 | Y5: =IF(AND(SCTR_Brokers[[#This Row],[Estado]]<>"FINALIZADO",SCTR_Brokers[[#This Row],[Plazo]]=LISTAS!$J$4),1,0) -> 0 | Z5: =IF(SCTR_Brokers[[#This Row],[Fecha_Solic_Informe]]="",0,1) -> 0 | AA5: =IF(SCTR_Brokers[[#This Row],[Fecha_Informe]]="",0,1) -> 0 | AB5: =IF(AND(SCTR_Brokers[[#This Row],[Fecha_Solic_Informe]]<>"",SCTR_Brokers[[#This Row],[Fecha_Informe]]=""),1,0) -> 0 | AC5: =IF(AND(SCTR_Brokers[[#This Row],[Fecha_Solic_Informe]]<>"",SCTR_Brokers[[#This Row],[Fecha_Informe]]<>""),ROUND((SCTR_Brokers[[#This Row],[Fecha_Informe]]-SCTR_Brokers[[#This Row],[Fecha_Solic_Informe]])*24,1),"")
A6: AAQkADdkNThjNzFkLWM0ZmMtNDJhYS04MDVlLTIwNzE4ZDI1Mzg4YgAQAJbH0u8xpU60thd9UB-4onM= | C6: =IF(SCTR_Brokers[[#This Row],[FechaRecepcion]]="","",SCTR_Brokers[[#This Row],[ConversationId]]&"-"&TEXT(SCTR_Brokers[[#This Row],[FechaRecepcion]],"aaaammddhhmmss")) -> AAQkADdkNThjNzFkLWM0ZmMtNDJhYS04MDVlLTIwNzE4ZDI1Mzg4YgAQAJbH0u8xpU60thd9UB-4onM=-20260813165004 | D6: RV: PUMARRUMI CASTILLO, BRYGEL: Solicitud 1131705 | E6: MARSH | F6: 46247.701 | G6: 46247.711 | H6: sctrsalud@mapfre.com.pe | I6: FINALIZADO | K6: SCTR SALUD | N6: =IF(SCTR_Brokers[[#This Row],[FechaRecepcion]]="","",IF(SCTR_Brokers[[#This Row],[Estado]]="FINALIZADO","",IF(SCTR_Brokers[[#This Row],[FechaUltimaRespuesta]]="","",_xlfn.LET(_xlpm.fer,LISTAS!$L$3:$L$100,_xlpm.ep,DATE(2000,1,1),_xlpm.ini,SCTR_Brokers[[#This Row],[FechaUltimaRespuesta]],_xlpm.fin,NOW(),_xlpm.dini,INT(_xlpm.ini),_xlpm.dfin,INT(_xlpm.fin),_xlpm.hini,9.5*NETWORKDAYS.INTL(_xlpm.ep,_xlpm.dini-1,"0000111",_xlpm.fer)+6*NETWORKDAYS.INTL(_xlpm.ep,_xlpm.dini-1,"1111011",_xlpm.fer)+IF(OR(WEEKDAY(_xlpm.dini,2)>5,COUNTIF(_xlpm.fer,_xlpm.dini)>0),0,MAX(0,MIN(_xlpm.ini-_xlpm.dini,IF(WEEKDAY(_xlpm.dini,2)=5,14/24,17.5/24))-8/24)*24),_xlpm.hfin,9.5*NETWORKDAYS.INTL(_xlpm.ep,_xlpm.dfin-1,"0000111",_xlpm.fer)+6*NETWORKDAYS.INTL(_xlpm.ep,_xlpm.dfin-1,"1111011",_xlpm.fer)+IF(OR(WEEKDAY(_xlpm.dfin,2)>5,COUNTIF(_xlpm.fer,_xlpm.dfin)>0),0,MAX(0,MIN(_xlpm.fin-_xlpm.dfin,IF(WEEKDAY(_xlpm.dfin,2)=5,14/24,17.5/24))-8/24)*24),ROUND(MAX(0,_xlpm.hfin-_xlpm.hini),1))))) | Q6: 46247.711 | R6: =IF(SCTR_Brokers[[#This Row],[FechaRecepcion]]="","",_xlfn.LET(_xlpm.fer,LISTAS!$L$3:$L$100,_xlpm.ep,DATE(2000,1,1),_xlpm.ini,SCTR_Brokers[[#This Row],[FechaRecepcion]],_xlpm.fin,IF(SCTR_Brokers[[#This Row],[Fecha_Cierre]]<>"",SCTR_Brokers[[#This Row],[Fecha_Cierre]],NOW()),_xlpm.dini,INT(_xlpm.ini),_xlpm.dfin,INT(_xlpm.fin),_xlpm.hini,9.5*NETWORKDAYS.INTL(_xlpm.ep,_xlpm.dini-1,"0000111",_xlpm.fer)+6*NETWORKDAYS.INTL(_xlpm.ep,_xlpm.dini-1,"1111011",_xlpm.fer)+IF(OR(WEEKDAY(_xlpm.dini,2)>5,COUNTIF(_xlpm.fer,_xlpm.dini)>0),0,MAX(0,MIN(_xlpm.ini-_xlpm.dini,IF(WEEKDAY(_xlpm.dini,2)=5,14/24,17.5/24))-8/24)*24),_xlpm.hfin,9.5*NETWORKDAYS.INTL(_xlpm.ep,_xlpm.dfin-1,"0000111",_xlpm.fer)+6*NETWORKDAYS.INTL(_xlpm.ep,_xlpm.dfin-1,"1111011",_xlpm.fer)+IF(OR(WEEKDAY(_xlpm.dfin,2)>5,COUNTIF(_xlpm.fer,_xlpm.dfin)>0),0,MAX(0,MIN(_xlpm.fin-_xlpm.dfin,IF(WEEKDAY(_xlpm.dfin,2)=5,14/24,17.5/24))-8/24)*24),_xlpm.hrs,IF(SCTR_Brokers[[#This Row],[Estado]]="FINALIZADO",MAX(0,_xlpm.hfin-_xlpm.hini),IF(SCTR_Brokers[[#This Row],[Horas_Transcurridas]]="",MAX(0,_xlpm.hfin-_xlpm.hini),SCTR_Brokers[[#This Row],[Horas_Transcurridas]])),IF(_xlpm.hrs<=LISTAS!$E$3,LISTAS!$J$3,LISTAS!$J$4))) -> Dentro | T6: =IF(SCTR_Brokers[[#This Row],[FechaRecepcion]]="","",TEXT(SCTR_Brokers[[#This Row],[FechaRecepcion]],"mmmm")&" "&YEAR(SCTR_Brokers[[#This Row],[FechaRecepcion]])) -> agosto 2026 | U6: =IF(SCTR_Brokers[[#This Row],[Estado]]="FINALIZADO",1,0) -> 1 | V6: =IF(SCTR_Brokers[[#This Row],[FechaRecepcion]]="","",IF(SCTR_Brokers[[#This Row],[Estado]]="FINALIZADO",0,1)) -> 0 | W6: =IF(AND(SCTR_Brokers[[#This Row],[Estado]]="FINALIZADO",SCTR_Brokers[[#This Row],[Plazo]]=LISTAS!$J$3),1,0) -> 1 | X6: =IF(AND(SCTR_Brokers[[#This Row],[Estado]]="FINALIZADO",SCTR_Brokers[[#This Row],[Plazo]]=LISTAS!$J$4),1,0) -> 0 | Y6: =IF(AND(SCTR_Brokers[[#This Row],[Estado]]<>"FINALIZADO",SCTR_Brokers[[#This Row],[Plazo]]=LISTAS!$J$4),1,0) -> 0 | Z6: =IF(SCTR_Brokers[[#This Row],[Fecha_Solic_Informe]]="",0,1) -> 0 | AA6: =IF(SCTR_Brokers[[#This Row],[Fecha_Informe]]="",0,1) -> 0 | AB6: =IF(AND(SCTR_Brokers[[#This Row],[Fecha_Solic_Informe]]<>"",SCTR_Brokers[[#This Row],[Fecha_Informe]]=""),1,0) -> 0 | AC6: =IF(AND(SCTR_Brokers[[#This Row],[Fecha_Solic_Informe]]<>"",SCTR_Brokers[[#This Row],[Fecha_Informe]]<>""),ROUND((SCTR_Brokers[[#This Row],[Fecha_Informe]]-SCTR_Brokers[[#This Row],[Fecha_Solic_Informe]])*24,1),"")
A7: AAQkADdkNThjNzFkLWM0ZmMtNDJhYS04MDVlLTIwNzE4ZDI1Mzg4YgAQAKj4wOyC3j1JjF2bNr2RW68= | C7: =IF(SCTR_Brokers[[#This Row],[FechaRecepcion]]="","",SCTR_Brokers[[#This Row],[ConversationId]]&"-"&TEXT(SCTR_Brokers[[#This Row],[FechaRecepcion]],"aaaammddhhmmss")) -> AAQkADdkNThjNzFkLWM0ZmMtNDJhYS04MDVlLTIwNzE4ZDI1Mzg4YgAQAKj4wOyC3j1JjF2bNr2RW68=-20260813172429 | D7: RV: ACCIDENTE DE TRABAJO- COLABORADOR COCINA EDDY AGUILAR VIZCARRA // APROBACION CARTA DE GARANTIA // SCTR SALUD - NESSUS HOTELES PERU | E7: MARSH | F7: 46247.725 | G7: 46248.498 | H7: sctrsalud@mapfre.com.pe | I7: FINALIZADO | K7: SCTR SALUD | N7: =IF(SCTR_Brokers[[#This Row],[FechaRecepcion]]="","",IF(SCTR_Brokers[[#This Row],[Estado]]="FINALIZADO","",IF(SCTR_Brokers[[#This Row],[FechaUltimaRespuesta]]="","",_xlfn.LET(_xlpm.fer,LISTAS!$L$3:$L$100,_xlpm.ep,DATE(2000,1,1),_xlpm.ini,SCTR_Brokers[[#This Row],[FechaUltimaRespuesta]],_xlpm.fin,NOW(),_xlpm.dini,INT(_xlpm.ini),_xlpm.dfin,INT(_xlpm.fin),_xlpm.hini,9.5*NETWORKDAYS.INTL(_xlpm.ep,_xlpm.dini-1,"0000111",_xlpm.fer)+6*NETWORKDAYS.INTL(_xlpm.ep,_xlpm.dini-1,"1111011",_xlpm.fer)+IF(OR(WEEKDAY(_xlpm.dini,2)>5,COUNTIF(_xlpm.fer,_xlpm.dini)>0),0,MAX(0,MIN(_xlpm.ini-_xlpm.dini,IF(WEEKDAY(_xlpm.dini,2)=5,14/24,17.5/24))-8/24)*24),_xlpm.hfin,9.5*NETWORKDAYS.INTL(_xlpm.ep,_xlpm.dfin-1,"0000111",_xlpm.fer)+6*NETWORKDAYS.INTL(_xlpm.ep,_xlpm.dfin-1,"1111011",_xlpm.fer)+IF(OR(WEEKDAY(_xlpm.dfin,2)>5,COUNTIF(_xlpm.fer,_xlpm.dfin)>0),0,MAX(0,MIN(_xlpm.fin-_xlpm.dfin,IF(WEEKDAY(_xlpm.dfin,2)=5,14/24,17.5/24))-8/24)*24),ROUND(MAX(0,_xlpm.hfin-_xlpm.hini),1))))) | Q7: 46248.498 | R7: =IF(SCTR_Brokers[[#This Row],[FechaRecepcion]]="","",_xlfn.LET(_xlpm.fer,LISTAS!$L$3:$L$100,_xlpm.ep,DATE(2000,1,1),_xlpm.ini,SCTR_Brokers[[#This Row],[FechaRecepcion]],_xlpm.fin,IF(SCTR_Brokers[[#This Row],[Fecha_Cierre]]<>"",SCTR_Brokers[[#This Row],[Fecha_Cierre]],NOW()),_xlpm.dini,INT(_xlpm.ini),_xlpm.dfin,INT(_xlpm.fin),_xlpm.hini,9.5*NETWORKDAYS.INTL(_xlpm.ep,_xlpm.dini-1,"0000111",_xlpm.fer)+6*NETWORKDAYS.INTL(_xlpm.ep,_xlpm.dini-1,"1111011",_xlpm.fer)+IF(OR(WEEKDAY(_xlpm.dini,2)>5,COUNTIF(_xlpm.fer,_xlpm.dini)>0),0,MAX(0,MIN(_xlpm.ini-_xlpm.dini,IF(WEEKDAY(_xlpm.dini,2)=5,14/24,17.5/24))-8/24)*24),_xlpm.hfin,9.5*NETWORKDAYS.INTL(_xlpm.ep,_xlpm.dfin-1,"0000111",_xlpm.fer)+6*NETWORKDAYS.INTL(_xlpm.ep,_xlpm.dfin-1,"1111011",_xlpm.fer)+IF(OR(WEEKDAY(_xlpm.dfin,2)>5,COUNTIF(_xlpm.fer,_xlpm.dfin)>0),0,MAX(0,MIN(_xlpm.fin-_xlpm.dfin,IF(WEEKDAY(_xlpm.dfin,2)=5,14/24,17.5/24))-8/24)*24),_xlpm.hrs,IF(SCTR_Brokers[[#This Row],[Estado]]="FINALIZADO",MAX(0,_xlpm.hfin-_xlpm.hini),IF(SCTR_Brokers[[#This Row],[Horas_Transcurridas]]="",MAX(0,_xlpm.hfin-_xlpm.hini),SCTR_Brokers[[#This Row],[Horas_Transcurridas]])),IF(_xlpm.hrs<=LISTAS!$E$3,LISTAS!$J$3,LISTAS!$J$4))) -> Dentro | T7: =IF(SCTR_Brokers[[#This Row],[FechaRecepcion]]="","",TEXT(SCTR_Brokers[[#This Row],[FechaRecepcion]],"mmmm")&" "&YEAR(SCTR_Brokers[[#This Row],[FechaRecepcion]])) -> agosto 2026 | U7: =IF(SCTR_Brokers[[#This Row],[Estado]]="FINALIZADO",1,0) -> 1 | V7: =IF(SCTR_Brokers[[#This Row],[FechaRecepcion]]="","",IF(SCTR_Brokers[[#This Row],[Estado]]="FINALIZADO",0,1)) -> 0 | W7: =IF(AND(SCTR_Brokers[[#This Row],[Estado]]="FINALIZADO",SCTR_Brokers[[#This Row],[Plazo]]=LISTAS!$J$3),1,0) -> 1 | X7: =IF(AND(SCTR_Brokers[[#This Row],[Estado]]="FINALIZADO",SCTR_Brokers[[#This Row],[Plazo]]=LISTAS!$J$4),1,0) -> 0 | Y7: =IF(AND(SCTR_Brokers[[#This Row],[Estado]]<>"FINALIZADO",SCTR_Brokers[[#This Row],[Plazo]]=LISTAS!$J$4),1,0) -> 0 | Z7: =IF(SCTR_Brokers[[#This Row],[Fecha_Solic_Informe]]="",0,1) -> 0 | AA7: =IF(SCTR_Brokers[[#This Row],[Fecha_Informe]]="",0,1) -> 0 | AB7: =IF(AND(SCTR_Brokers[[#This Row],[Fecha_Solic_Informe]]<>"",SCTR_Brokers[[#This Row],[Fecha_Informe]]=""),1,0) -> 0 | AC7: =IF(AND(SCTR_Brokers[[#This Row],[Fecha_Solic_Informe]]<>"",SCTR_Brokers[[#This Row],[Fecha_Informe]]<>""),ROUND((SCTR_Brokers[[#This Row],[Fecha_Informe]]-SCTR_Brokers[[#This Row],[Fecha_Solic_Informe]])*24,1),"")
A8: AAQkADdkNThjNzFkLWM0ZmMtNDJhYS04MDVlLTIwNzE4ZDI1Mzg4YgAQAEWL9Z2HU35Ah8_6EELq5Sc= | C8: =IF(SCTR_Brokers[[#This Row],[FechaRecepcion]]="","",SCTR_Brokers[[#This Row],[ConversationId]]&"-"&TEXT(SCTR_Brokers[[#This Row],[FechaRecepcion]],"aaaammddhhmmss")) -> AAQkADdkNThjNzFkLWM0ZmMtNDJhYS04MDVlLTIwNzE4ZDI1Mzg4YgAQAEWL9Z2HU35Ah8_6EELq5Sc=-20260813173727 | D8: CENCOSUD RETAIL PERU S.A. - AP - BACALLA GUTIERREZ LEYZI CAROLA - CONSULTA DE ACTIVACION AP | E8: ARTHUR GALLAGHER | F8: 46247.734 | G8: 46247.749 | H8: sctrsalud@mapfre.com.pe | I8: FINALIZADO | K8: SCTR SALUD | N8: =IF(SCTR_Brokers[[#This Row],[FechaRecepcion]]="","",IF(SCTR_Brokers[[#This Row],[Estado]]="FINALIZADO","",IF(SCTR_Brokers[[#This Row],[FechaUltimaRespuesta]]="","",_xlfn.LET(_xlpm.fer,LISTAS!$L$3:$L$100,_xlpm.ep,DATE(2000,1,1),_xlpm.ini,SCTR_Brokers[[#This Row],[FechaUltimaRespuesta]],_xlpm.fin,NOW(),_xlpm.dini,INT(_xlpm.ini),_xlpm.dfin,INT(_xlpm.fin),_xlpm.hini,9.5*NETWORKDAYS.INTL(_xlpm.ep,_xlpm.dini-1,"0000111",_xlpm.fer)+6*NETWORKDAYS.INTL(_xlpm.ep,_xlpm.dini-1,"1111011",_xlpm.fer)+IF(OR(WEEKDAY(_xlpm.dini,2)>5,COUNTIF(_xlpm.fer,_xlpm.dini)>0),0,MAX(0,MIN(_xlpm.ini-_xlpm.dini,IF(WEEKDAY(_xlpm.dini,2)=5,14/24,17.5/24))-8/24)*24),_xlpm.hfin,9.5*NETWORKDAYS.INTL(_xlpm.ep,_xlpm.dfin-1,"0000111",_xlpm.fer)+6*NETWORKDAYS.INTL(_xlpm.ep,_xlpm.dfin-1,"1111011",_xlpm.fer)+IF(OR(WEEKDAY(_xlpm.dfin,2)>5,COUNTIF(_xlpm.fer,_xlpm.dfin)>0),0,MAX(0,MIN(_xlpm.fin-_xlpm.dfin,IF(WEEKDAY(_xlpm.dfin,2)=5,14/24,17.5/24))-8/24)*24),ROUND(MAX(0,_xlpm.hfin-_xlpm.hini),1))))) | Q8: 46247.749 | R8: =IF(SCTR_Brokers[[#This Row],[FechaRecepcion]]="","",_xlfn.LET(_xlpm.fer,LISTAS!$L$3:$L$100,_xlpm.ep,DATE(2000,1,1),_xlpm.ini,SCTR_Brokers[[#This Row],[FechaRecepcion]],_xlpm.fin,IF(SCTR_Brokers[[#This Row],[Fecha_Cierre]]<>"",SCTR_Brokers[[#This Row],[Fecha_Cierre]],NOW()),_xlpm.dini,INT(_xlpm.ini),_xlpm.dfin,INT(_xlpm.fin),_xlpm.hini,9.5*NETWORKDAYS.INTL(_xlpm.ep,_xlpm.dini-1,"0000111",_xlpm.fer)+6*NETWORKDAYS.INTL(_xlpm.ep,_xlpm.dini-1,"1111011",_xlpm.fer)+IF(OR(WEEKDAY(_xlpm.dini,2)>5,COUNTIF(_xlpm.fer,_xlpm.dini)>0),0,MAX(0,MIN(_xlpm.ini-_xlpm.dini,IF(WEEKDAY(_xlpm.dini,2)=5,14/24,17.5/24))-8/24)*24),_xlpm.hfin,9.5*NETWORKDAYS.INTL(_xlpm.ep,_xlpm.dfin-1,"0000111",_xlpm.fer)+6*NETWORKDAYS.INTL(_xlpm.ep,_xlpm.dfin-1,"1111011",_xlpm.fer)+IF(OR(WEEKDAY(_xlpm.dfin,2)>5,COUNTIF(_xlpm.fer,_xlpm.dfin)>0),0,MAX(0,MIN(_xlpm.fin-_xlpm.dfin,IF(WEEKDAY(_xlpm.dfin,2)=5,14/24,17.5/24))-8/24)*24),_xlpm.hrs,IF(SCTR_Brokers[[#This Row],[Estado]]="FINALIZADO",MAX(0,_xlpm.hfin-_xlpm.hini),IF(SCTR_Brokers[[#This Row],[Horas_Transcurridas]]="",MAX(0,_xlpm.hfin-_xlpm.hini),SCTR_Brokers[[#This Row],[Horas_Transcurridas]])),IF(_xlpm.hrs<=LISTAS!$E$3,LISTAS!$J$3,LISTAS!$J$4))) -> Dentro | T8: =IF(SCTR_Brokers[[#This Row],[FechaRecepcion]]="","",TEXT(SCTR_Brokers[[#This Row],[FechaRecepcion]],"mmmm")&" "&YEAR(SCTR_Brokers[[#This Row],[FechaRecepcion]])) -> agosto 2026 | U8: =IF(SCTR_Brokers[[#This Row],[Estado]]="FINALIZADO",1,0) -> 1 | V8: =IF(SCTR_Brokers[[#This Row],[FechaRecepcion]]="","",IF(SCTR_Brokers[[#This Row],[Estado]]="FINALIZADO",0,1)) -> 0 | W8: =IF(AND(SCTR_Brokers[[#This Row],[Estado]]="FINALIZADO",SCTR_Brokers[[#This Row],[Plazo]]=LISTAS!$J$3),1,0) -> 1 | X8: =IF(AND(SCTR_Brokers[[#This Row],[Estado]]="FINALIZADO",SCTR_Brokers[[#This Row],[Plazo]]=LISTAS!$J$4),1,0) -> 0 | Y8: =IF(AND(SCTR_Brokers[[#This Row],[Estado]]<>"FINALIZADO",SCTR_Brokers[[#This Row],[Plazo]]=LISTAS!$J$4),1,0) -> 0 | Z8: =IF(SCTR_Brokers[[#This Row],[Fecha_Solic_Informe]]="",0,1) -> 0 | AA8: =IF(SCTR_Brokers[[#This Row],[Fecha_Informe]]="",0,1) -> 0 | AB8: =IF(AND(SCTR_Brokers[[#This Row],[Fecha_Solic_Informe]]<>"",SCTR_Brokers[[#This Row],[Fecha_Informe]]=""),1,0) -> 0 | AC8: =IF(AND(SCTR_Brokers[[#This Row],[Fecha_Solic_Informe]]<>"",SCTR_Brokers[[#This Row],[Fecha_Informe]]<>""),ROUND((SCTR_Brokers[[#This Row],[Fecha_Informe]]-SCTR_Brokers[[#This Row],[Fecha_Solic_Informe]])*24,1),"")
A9: AAQkADdkNThjNzFkLWM0ZmMtNDJhYS04MDVlLTIwNzE4ZDI1Mzg4YgAQAEvkGJ0JTE4hpm6yW1eczK8= | C9: =IF(SCTR_Brokers[[#This Row],[FechaRecepcion]]="","",SCTR_Brokers[[#This Row],[ConversationId]]&"-"&TEXT(SCTR_Brokers[[#This Row],[FechaRecepcion]],"aaaammddhhmmss")) -> AAQkADdkNThjNzFkLWM0ZmMtNDJhYS04MDVlLTIwNzE4ZDI1Mzg4YgAQAEvkGJ0JTE4hpm6yW1eczK8=-20260813174900 | D9: RE: AMABLE RECORDATORIO RE: REVISION DEL CASO- CENTENO MOYOPAZ JAVIER DE NILSON- SCTR SALUD MAPFRE- PROVEFABRICA DEL PERU SOCIEDAD ANONIMA | E9: HOWDEN | F9: 46247.742 | G9: 46251.474 | H9: sctrsalud@mapfre.com.pe | I9: FINALIZADO | K9: SCTR SALUD | N9: =IF(SCTR_Brokers[[#This Row],[FechaRecepcion]]="","",IF(SCTR_Brokers[[#This Row],[Estado]]="FINALIZADO","",IF(SCTR_Brokers[[#This Row],[FechaUltimaRespuesta]]="","",_xlfn.LET(_xlpm.fer,LISTAS!$L$3:$L$100,_xlpm.ep,DATE(2000,1,1),_xlpm.ini,SCTR_Brokers[[#This Row],[FechaUltimaRespuesta]],_xlpm.fin,NOW(),_xlpm.dini,INT(_xlpm.ini),_xlpm.dfin,INT(_xlpm.fin),_xlpm.hini,9.5*NETWORKDAYS.INTL(_xlpm.ep,_xlpm.dini-1,"0000111",_xlpm.fer)+6*NETWORKDAYS.INTL(_xlpm.ep,_xlpm.dini-1,"1111011",_xlpm.fer)+IF(OR(WEEKDAY(_xlpm.dini,2)>5,COUNTIF(_xlpm.fer,_xlpm.dini)>0),0,MAX(0,MIN(_xlpm.ini-_xlpm.dini,IF(WEEKDAY(_xlpm.dini,2)=5,14/24,17.5/24))-8/24)*24),_xlpm.hfin,9.5*NETWORKDAYS.INTL(_xlpm.ep,_xlpm.dfin-1,"0000111",_xlpm.fer)+6*NETWORKDAYS.INTL(_xlpm.ep,_xlpm.dfin-1,"1111011",_xlpm.fer)+IF(OR(WEEKDAY(_xlpm.dfin,2)>5,COUNTIF(_xlpm.fer,_xlpm.dfin)>0),0,MAX(0,MIN(_xlpm.fin-_xlpm.dfin,IF(WEEKDAY(_xlpm.dfin,2)=5,14/24,17.5/24))-8/24)*24),ROUND(MAX(0,_xlpm.hfin-_xlpm.hini),1))))) | Q9: 46251.474 | R9: =IF(SCTR_Brokers[[#This Row],[FechaRecepcion]]="","",_xlfn.LET(_xlpm.fer,LISTAS!$L$3:$L$100,_xlpm.ep,DATE(2000,1,1),_xlpm.ini,SCTR_Brokers[[#This Row],[FechaRecepcion]],_xlpm.fin,IF(SCTR_Brokers[[#This Row],[Fecha_Cierre]]<>"",SCTR_Brokers[[#This Row],[Fecha_Cierre]],NOW()),_xlpm.dini,INT(_xlpm.ini),_xlpm.dfin,INT(_xlpm.fin),_xlpm.hini,9.5*NETWORKDAYS.INTL(_xlpm.ep,_xlpm.dini-1,"0000111",_xlpm.fer)+6*NETWORKDAYS.INTL(_xlpm.ep,_xlpm.dini-1,"1111011",_xlpm.fer)+IF(OR(WEEKDAY(_xlpm.dini,2)>5,COUNTIF(_xlpm.fer,_xlpm.dini)>0),0,MAX(0,MIN(_xlpm.ini-_xlpm.dini,IF(WEEKDAY(_xlpm.dini,2)=5,14/24,17.5/24))-8/24)*24),_xlpm.hfin,9.5*NETWORKDAYS.INTL(_xlpm.ep,_xlpm.dfin-1,"0000111",_xlpm.fer)+6*NETWORKDAYS.INTL(_xlpm.ep,_xlpm.dfin-1,"1111011",_xlpm.fer)+IF(OR(WEEKDAY(_xlpm.dfin,2)>5,COUNTIF(_xlpm.fer,_xlpm.dfin)>0),0,MAX(0,MIN(_xlpm.fin-_xlpm.dfin,IF(WEEKDAY(_xlpm.dfin,2)=5,14/24,17.5/24))-8/24)*24),_xlpm.hrs,IF(SCTR_Brokers[[#This Row],[Estado]]="FINALIZADO",MAX(0,_xlpm.hfin-_xlpm.hini),IF(SCTR_Brokers[[#This Row],[Horas_Transcurridas]]="",MAX(0,_xlpm.hfin-_xlpm.hini),SCTR_Brokers[[#This Row],[Horas_Transcurridas]])),IF(_xlpm.hrs<=LISTAS!$E$3,LISTAS!$J$3,LISTAS!$J$4))) -> Fuera | T9: =IF(SCTR_Brokers[[#This Row],[FechaRecepcion]]="","",TEXT(SCTR_Brokers[[#This Row],[FechaRecepcion]],"mmmm")&" "&YEAR(SCTR_Brokers[[#This Row],[FechaRecepcion]])) -> agosto 2026 | U9: =IF(SCTR_Brokers[[#This Row],[Estado]]="FINALIZADO",1,0) -> 1 | V9: =IF(SCTR_Brokers[[#This Row],[FechaRecepcion]]="","",IF(SCTR_Brokers[[#This Row],[Estado]]="FINALIZADO",0,1)) -> 0 | W9: =IF(AND(SCTR_Brokers[[#This Row],[Estado]]="FINALIZADO",SCTR_Brokers[[#This Row],[Plazo]]=LISTAS!$J$3),1,0) -> 0 | X9: =IF(AND(SCTR_Brokers[[#This Row],[Estado]]="FINALIZADO",SCTR_Brokers[[#This Row],[Plazo]]=LISTAS!$J$4),1,0) -> 1 | Y9: =IF(AND(SCTR_Brokers[[#This Row],[Estado]]<>"FINALIZADO",SCTR_Brokers[[#This Row],[Plazo]]=LISTAS!$J$4),1,0) -> 0 | Z9: =IF(SCTR_Brokers[[#This Row],[Fecha_Solic_Informe]]="",0,1) -> 0 | AA9: =IF(SCTR_Brokers[[#This Row],[Fecha_Informe]]="",0,1) -> 0 | AB9: =IF(AND(SCTR_Brokers[[#This Row],[Fecha_Solic_Informe]]<>"",SCTR_Brokers[[#This Row],[Fecha_Informe]]=""),1,0) -> 0 | AC9: =IF(AND(SCTR_Brokers[[#This Row],[Fecha_Solic_Informe]]<>"",SCTR_Brokers[[#This Row],[Fecha_Informe]]<>""),ROUND((SCTR_Brokers[[#This Row],[Fecha_Informe]]-SCTR_Brokers[[#This Row],[Fecha_Solic_Informe]])*24,1),"")
A10: AAQkADdkNThjNzFkLWM0ZmMtNDJhYS04MDVlLTIwNzE4ZDI1Mzg4YgAQAIcHvAvKE042nOSk-cjbPIc= | C10: =IF(SCTR_Brokers[[#This Row],[FechaRecepcion]]="","",SCTR_Brokers[[#This Row],[ConversationId]]&"-"&TEXT(SCTR_Brokers[[#This Row],[FechaRecepcion]],"aaaammddhhmmss")) -> AAQkADdkNThjNzFkLWM0ZmMtNDJhYS04MDVlLTIwNzE4ZDI1Mzg4YgAQAIcHvAvKE042nOSk-cjbPIc=-20260813220218 | D10: RE: LAP - MAPFRE SCTR SALUD - ASEG. RAUL PAY TAN - SOLICITUD DE ACTIVACION AT POR PICADURA DE INSECTO | E10: ARTHUR GALLAGHER | F10: 46247.918 | G10: 46248.547 | H10: sctrsalud@mapfre.com.pe | I10: FINALIZADO | K10: SCTR SALUD | N10: =IF(SCTR_Brokers[[#This Row],[FechaRecepcion]]="","",IF(SCTR_Brokers[[#This Row],[Estado]]="FINALIZADO","",IF(SCTR_Brokers[[#This Row],[FechaUltimaRespuesta]]="","",_xlfn.LET(_xlpm.fer,LISTAS!$L$3:$L$100,_xlpm.ep,DATE(2000,1,1),_xlpm.ini,SCTR_Brokers[[#This Row],[FechaUltimaRespuesta]],_xlpm.fin,NOW(),_xlpm.dini,INT(_xlpm.ini),_xlpm.dfin,INT(_xlpm.fin),_xlpm.hini,9.5*NETWORKDAYS.INTL(_xlpm.ep,_xlpm.dini-1,"0000111",_xlpm.fer)+6*NETWORKDAYS.INTL(_xlpm.ep,_xlpm.dini-1,"1111011",_xlpm.fer)+IF(OR(WEEKDAY(_xlpm.dini,2)>5,COUNTIF(_xlpm.fer,_xlpm.dini)>0),0,MAX(0,MIN(_xlpm.ini-_xlpm.dini,IF(WEEKDAY(_xlpm.dini,2)=5,14/24,17.5/24))-8/24)*24),_xlpm.hfin,9.5*NETWORKDAYS.INTL(_xlpm.ep,_xlpm.dfin-1,"0000111",_xlpm.fer)+6*NETWORKDAYS.INTL(_xlpm.ep,_xlpm.dfin-1,"1111011",_xlpm.fer)+IF(OR(WEEKDAY(_xlpm.dfin,2)>5,COUNTIF(_xlpm.fer,_xlpm.dfin)>0),0,MAX(0,MIN(_xlpm.fin-_xlpm.dfin,IF(WEEKDAY(_xlpm.dfin,2)=5,14/24,17.5/24))-8/24)*24),ROUND(MAX(0,_xlpm.hfin-_xlpm.hini),1))))) | Q10: 46248.547 | R10: =IF(SCTR_Brokers[[#This Row],[FechaRecepcion]]="","",_xlfn.LET(_xlpm.fer,LISTAS!$L$3:$L$100,_xlpm.ep,DATE(2000,1,1),_xlpm.ini,SCTR_Brokers[[#This Row],[FechaRecepcion]],_xlpm.fin,IF(SCTR_Brokers[[#This Row],[Fecha_Cierre]]<>"",SCTR_Brokers[[#This Row],[Fecha_Cierre]],NOW()),_xlpm.dini,INT(_xlpm.ini),_xlpm.dfin,INT(_xlpm.fin),_xlpm.hini,9.5*NETWORKDAYS.INTL(_xlpm.ep,_xlpm.dini-1,"0000111",_xlpm.fer)+6*NETWORKDAYS.INTL(_xlpm.ep,_xlpm.dini-1,"1111011",_xlpm.fer)+IF(OR(WEEKDAY(_xlpm.dini,2)>5,COUNTIF(_xlpm.fer,_xlpm.dini)>0),0,MAX(0,MIN(_xlpm.ini-_xlpm.dini,IF(WEEKDAY(_xlpm.dini,2)=5,14/24,17.5/24))-8/24)*24),_xlpm.hfin,9.5*NETWORKDAYS.INTL(_xlpm.ep,_xlpm.dfin-1,"0000111",_xlpm.fer)+6*NETWORKDAYS.INTL(_xlpm.ep,_xlpm.dfin-1,"1111011",_xlpm.fer)+IF(OR(WEEKDAY(_xlpm.dfin,2)>5,COUNTIF(_xlpm.fer,_xlpm.dfin)>0),0,MAX(0,MIN(_xlpm.fin-_xlpm.dfin,IF(WEEKDAY(_xlpm.dfin,2)=5,14/24,17.5/24))-8/24)*24),_xlpm.hrs,IF(SCTR_Brokers[[#This Row],[Estado]]="FINALIZADO",MAX(0,_xlpm.hfin-_xlpm.hini),IF(SCTR_Brokers[[#This Row],[Horas_Transcurridas]]="",MAX(0,_xlpm.hfin-_xlpm.hini),SCTR_Brokers[[#This Row],[Horas_Transcurridas]])),IF(_xlpm.hrs<=LISTAS!$E$3,LISTAS!$J$3,LISTAS!$J$4))) -> Dentro | T10: =IF(SCTR_Brokers[[#This Row],[FechaRecepcion]]="","",TEXT(SCTR_Brokers[[#This Row],[FechaRecepcion]],"mmmm")&" "&YEAR(SCTR_Brokers[[#This Row],[FechaRecepcion]])) -> agosto 2026 | U10: =IF(SCTR_Brokers[[#This Row],[Estado]]="FINALIZADO",1,0) -> 1 | V10: =IF(SCTR_Brokers[[#This Row],[FechaRecepcion]]="","",IF(SCTR_Brokers[[#This Row],[Estado]]="FINALIZADO",0,1)) -> 0 | W10: =IF(AND(SCTR_Brokers[[#This Row],[Estado]]="FINALIZADO",SCTR_Brokers[[#This Row],[Plazo]]=LISTAS!$J$3),1,0) -> 1 | X10: =IF(AND(SCTR_Brokers[[#This Row],[Estado]]="FINALIZADO",SCTR_Brokers[[#This Row],[Plazo]]=LISTAS!$J$4),1,0) -> 0 | Y10: =IF(AND(SCTR_Brokers[[#This Row],[Estado]]<>"FINALIZADO",SCTR_Brokers[[#This Row],[Plazo]]=LISTAS!$J$4),1,0) -> 0 | Z10: =IF(SCTR_Brokers[[#This Row],[Fecha_Solic_Informe]]="",0,1) -> 0 | AA10: =IF(SCTR_Brokers[[#This Row],[Fecha_Informe]]="",0,1) -> 0 | AB10: =IF(AND(SCTR_Brokers[[#This Row],[Fecha_Solic_Informe]]<>"",SCTR_Brokers[[#This Row],[Fecha_Informe]]=""),1,0) -> 0 | AC10: =IF(AND(SCTR_Brokers[[#This Row],[Fecha_Solic_Informe]]<>"",SCTR_Brokers[[#This Row],[Fecha_Informe]]<>""),ROUND((SCTR_Brokers[[#This Row],[Fecha_Informe]]-SCTR_Brokers[[#This Row],[Fecha_Solic_Informe]])*24,1),"")
A11: AAQkADdkNThjNzFkLWM0ZmMtNDJhYS04MDVlLTIwNzE4ZDI1Mzg4YgAQAE6KChvywltLjo3Y0Mnsb3U= | C11: =IF(SCTR_Brokers[[#This Row],[FechaRecepcion]]="","",SCTR_Brokers[[#This Row],[ConversationId]]&"-"&TEXT(SCTR_Brokers[[#This Row],[FechaRecepcion]],"aaaammddhhmmss")) -> AAQkADdkNThjNzFkLWM0ZmMtNDJhYS04MDVlLTIwNzE4ZDI1Mzg4YgAQAE6KChvywltLjo3Y0Mnsb3U=-20260813220517 | D11: RE: LIMA AIRPORT PARTNERS / SCTR / Chang Ramirez, Jorge Luis | E11: ARTHUR GALLAGHER | F11: 46247.92 | G11: 46248.538 | H11: sctrsalud@mapfre.com.pe | I11: FINALIZADO | K11: SCTR SALUD | N11: =IF(SCTR_Brokers[[#This Row],[FechaRecepcion]]="","",IF(SCTR_Brokers[[#This Row],[Estado]]="FINALIZADO","",IF(SCTR_Brokers[[#This Row],[FechaUltimaRespuesta]]="","",_xlfn.LET(_xlpm.fer,LISTAS!$L$3:$L$100,_xlpm.ep,DATE(2000,1,1),_xlpm.ini,SCTR_Brokers[[#This Row],[FechaUltimaRespuesta]],_xlpm.fin,NOW(),_xlpm.dini,INT(_xlpm.ini),_xlpm.dfin,INT(_xlpm.fin),_xlpm.hini,9.5*NETWORKDAYS.INTL(_xlpm.ep,_xlpm.dini-1,"0000111",_xlpm.fer)+6*NETWORKDAYS.INTL(_xlpm.ep,_xlpm.dini-1,"1111011",_xlpm.fer)+IF(OR(WEEKDAY(_xlpm.dini,2)>5,COUNTIF(_xlpm.fer,_xlpm.dini)>0),0,MAX(0,MIN(_xlpm.ini-_xlpm.dini,IF(WEEKDAY(_xlpm.dini,2)=5,14/24,17.5/24))-8/24)*24),_xlpm.hfin,9.5*NETWORKDAYS.INTL(_xlpm.ep,_xlpm.dfin-1,"0000111",_xlpm.fer)+6*NETWORKDAYS.INTL(_xlpm.ep,_xlpm.dfin-1,"1111011",_xlpm.fer)+IF(OR(WEEKDAY(_xlpm.dfin,2)>5,COUNTIF(_xlpm.fer,_xlpm.dfin)>0),0,MAX(0,MIN(_xlpm.fin-_xlpm.dfin,IF(WEEKDAY(_xlpm.dfin,2)=5,14/24,17.5/24))-8/24)*24),ROUND(MAX(0,_xlpm.hfin-_xlpm.hini),1))))) | Q11: 46248.538 | R11: =IF(SCTR_Brokers[[#This Row],[FechaRecepcion]]="","",_xlfn.LET(_xlpm.fer,LISTAS!$L$3:$L$100,_xlpm.ep,DATE(2000,1,1),_xlpm.ini,SCTR_Brokers[[#This Row],[FechaRecepcion]],_xlpm.fin,IF(SCTR_Brokers[[#This Row],[Fecha_Cierre]]<>"",SCTR_Brokers[[#This Row],[Fecha_Cierre]],NOW()),_xlpm.dini,INT(_xlpm.ini),_xlpm.dfin,INT(_xlpm.fin),_xlpm.hini,9.5*NETWORKDAYS.INTL(_xlpm.ep,_xlpm.dini-1,"0000111",_xlpm.fer)+6*NETWORKDAYS.INTL(_xlpm.ep,_xlpm.dini-1,"1111011",_xlpm.fer)+IF(OR(WEEKDAY(_xlpm.dini,2)>5,COUNTIF(_xlpm.fer,_xlpm.dini)>0),0,MAX(0,MIN(_xlpm.ini-_xlpm.dini,IF(WEEKDAY(_xlpm.dini,2)=5,14/24,17.5/24))-8/24)*24),_xlpm.hfin,9.5*NETWORKDAYS.INTL(_xlpm.ep,_xlpm.dfin-1,"0000111",_xlpm.fer)+6*NETWORKDAYS.INTL(_xlpm.ep,_xlpm.dfin-1,"1111011",_xlpm.fer)+IF(OR(WEEKDAY(_xlpm.dfin,2)>5,COUNTIF(_xlpm.fer,_xlpm.dfin)>0),0,MAX(0,MIN(_xlpm.fin-_xlpm.dfin,IF(WEEKDAY(_xlpm.dfin,2)=5,14/24,17.5/24))-8/24)*24),_xlpm.hrs,IF(SCTR_Brokers[[#This Row],[Estado]]="FINALIZADO",MAX(0,_xlpm.hfin-_xlpm.hini),IF(SCTR_Brokers[[#This Row],[Horas_Transcurridas]]="",MAX(0,_xlpm.hfin-_xlpm.hini),SCTR_Brokers[[#This Row],[Horas_Transcurridas]])),IF(_xlpm.hrs<=LISTAS!$E$3,LISTAS!$J$3,LISTAS!$J$4))) -> Dentro | T11: =IF(SCTR_Brokers[[#This Row],[FechaRecepcion]]="","",TEXT(SCTR_Brokers[[#This Row],[FechaRecepcion]],"mmmm")&" "&YEAR(SCTR_Brokers[[#This Row],[FechaRecepcion]])) -> agosto 2026 | U11: =IF(SCTR_Brokers[[#This Row],[Estado]]="FINALIZADO",1,0) -> 1 | V11: =IF(SCTR_Brokers[[#This Row],[FechaRecepcion]]="","",IF(SCTR_Brokers[[#This Row],[Estado]]="FINALIZADO",0,1)) -> 0 | W11: =IF(AND(SCTR_Brokers[[#This Row],[Estado]]="FINALIZADO",SCTR_Brokers[[#This Row],[Plazo]]=LISTAS!$J$3),1,0) -> 1 | X11: =IF(AND(SCTR_Brokers[[#This Row],[Estado]]="FINALIZADO",SCTR_Brokers[[#This Row],[Plazo]]=LISTAS!$J$4),1,0) -> 0 | Y11: =IF(AND(SCTR_Brokers[[#This Row],[Estado]]<>"FINALIZADO",SCTR_Brokers[[#This Row],[Plazo]]=LISTAS!$J$4),1,0) -> 0 | Z11: =IF(SCTR_Brokers[[#This Row],[Fecha_Solic_Informe]]="",0,1) -> 0 | AA11: =IF(SCTR_Brokers[[#This Row],[Fecha_Informe]]="",0,1) -> 0 | AB11: =IF(AND(SCTR_Brokers[[#This Row],[Fecha_Solic_Informe]]<>"",SCTR_Brokers[[#This Row],[Fecha_Informe]]=""),1,0) -> 0 | AC11: =IF(AND(SCTR_Brokers[[#This Row],[Fecha_Solic_Informe]]<>"",SCTR_Brokers[[#This Row],[Fecha_Informe]]<>""),ROUND((SCTR_Brokers[[#This Row],[Fecha_Informe]]-SCTR_Brokers[[#This Row],[Fecha_Solic_Informe]])*24,1),"")
A12: AAQkADdkNThjNzFkLWM0ZmMtNDJhYS04MDVlLTIwNzE4ZDI1Mzg4YgAQAGNYmKV8CwNGkjfWksK0qfg= | C12: =IF(SCTR_Brokers[[#This Row],[FechaRecepcion]]="","",SCTR_Brokers[[#This Row],[ConversationId]]&"-"&TEXT(SCTR_Brokers[[#This Row],[FechaRecepcion]],"aaaammddhhmmss")) -> AAQkADdkNThjNzFkLWM0ZmMtNDJhYS04MDVlLTIwNzE4ZDI1Mzg4YgAQAGNYmKV8CwNGkjfWksK0qfg=-20260814091313 | D12: HOMECENTERS PERUANOS // SINIESTRO SCTR // PACIENTE ELJAER FERNANDO CHICCHI HUAMAN | E12: MARSH | F12: 46248.384 | G12: 46248.384 | H12: Brenda.Salazar@mercermarshbeneficios.com | I12: FINALIZADO | K12: SCTR SALUD | N12: =IF(SCTR_Brokers[[#This Row],[FechaRecepcion]]="","",IF(SCTR_Brokers[[#This Row],[Estado]]="FINALIZADO","",IF(SCTR_Brokers[[#This Row],[FechaUltimaRespuesta]]="","",_xlfn.LET(_xlpm.fer,LISTAS!$L$3:$L$100,_xlpm.ep,DATE(2000,1,1),_xlpm.ini,SCTR_Brokers[[#This Row],[FechaUltimaRespuesta]],_xlpm.fin,NOW(),_xlpm.dini,INT(_xlpm.ini),_xlpm.dfin,INT(_xlpm.fin),_xlpm.hini,9.5*NETWORKDAYS.INTL(_xlpm.ep,_xlpm.dini-1,"0000111",_xlpm.fer)+6*NETWORKDAYS.INTL(_xlpm.ep,_xlpm.dini-1,"1111011",_xlpm.fer)+IF(OR(WEEKDAY(_xlpm.dini,2)>5,COUNTIF(_xlpm.fer,_xlpm.dini)>0),0,MAX(0,MIN(_xlpm.ini-_xlpm.dini,IF(WEEKDAY(_xlpm.dini,2)=5,14/24,17.5/24))-8/24)*24),_xlpm.hfin,9.5*NETWORKDAYS.INTL(_xlpm.ep,_xlpm.dfin-1,"0000111",_xlpm.fer)+6*NETWORKDAYS.INTL(_xlpm.ep,_xlpm.dfin-1,"1111011",_xlpm.fer)+IF(OR(WEEKDAY(_xlpm.dfin,2)>5,COUNTIF(_xlpm.fer,_xlpm.dfin)>0),0,MAX(0,MIN(_xlpm.fin-_xlpm.dfin,IF(WEEKDAY(_xlpm.dfin,2)=5,14/24,17.5/24))-8/24)*24),ROUND(MAX(0,_xlpm.hfin-_xlpm.hini),1))))) | Q12: 46248.594 | R12: =IF(SCTR_Brokers[[#This Row],[FechaRecepcion]]="","",_xlfn.LET(_xlpm.fer,LISTAS!$L$3:$L$100,_xlpm.ep,DATE(2000,1,1),_xlpm.ini,SCTR_Brokers[[#This Row],[FechaRecepcion]],_xlpm.fin,IF(SCTR_Brokers[[#This Row],[Fecha_Cierre]]<>"",SCTR_Brokers[[#This Row],[Fecha_Cierre]],NOW()),_xlpm.dini,INT(_xlpm.ini),_xlpm.dfin,INT(_xlpm.fin),_xlpm.hini,9.5*NETWORKDAYS.INTL(_xlpm.ep,_xlpm.dini-1,"0000111",_xlpm.fer)+6*NETWORKDAYS.INTL(_xlpm.ep,_xlpm.dini-1,"1111011",_xlpm.fer)+IF(OR(WEEKDAY(_xlpm.dini,2)>5,COUNTIF(_xlpm.fer,_xlpm.dini)>0),0,MAX(0,MIN(_xlpm.ini-_xlpm.dini,IF(WEEKDAY(_xlpm.dini,2)=5,14/24,17.5/24))-8/24)*24),_xlpm.hfin,9.5*NETWORKDAYS.INTL(_xlpm.ep,_xlpm.dfin-1,"0000111",_xlpm.fer)+6*NETWORKDAYS.INTL(_xlpm.ep,_xlpm.dfin-1,"1111011",_xlpm.fer)+IF(OR(WEEKDAY(_xlpm.dfin,2)>5,COUNTIF(_xlpm.fer,_xlpm.dfin)>0),0,MAX(0,MIN(_xlpm.fin-_xlpm.dfin,IF(WEEKDAY(_xlpm.dfin,2)=5,14/24,17.5/24))-8/24)*24),_xlpm.hrs,IF(SCTR_Brokers[[#This Row],[Estado]]="FINALIZADO",MAX(0,_xlpm.hfin-_xlpm.hini),IF(SCTR_Brokers[[#This Row],[Horas_Transcurridas]]="",MAX(0,_xlpm.hfin-_xlpm.hini),SCTR_Brokers[[#This Row],[Horas_Transcurridas]])),IF(_xlpm.hrs<=LISTAS!$E$3,LISTAS!$J$3,LISTAS!$J$4))) -> Dentro | T12: =IF(SCTR_Brokers[[#This Row],[FechaRecepcion]]="","",TEXT(SCTR_Brokers[[#This Row],[FechaRecepcion]],"mmmm")&" "&YEAR(SCTR_Brokers[[#This Row],[FechaRecepcion]])) -> agosto 2026 | U12: =IF(SCTR_Brokers[[#This Row],[Estado]]="FINALIZADO",1,0) -> 1 | V12: =IF(SCTR_Brokers[[#This Row],[FechaRecepcion]]="","",IF(SCTR_Brokers[[#This Row],[Estado]]="FINALIZADO",0,1)) -> 0 | W12: =IF(AND(SCTR_Brokers[[#This Row],[Estado]]="FINALIZADO",SCTR_Brokers[[#This Row],[Plazo]]=LISTAS!$J$3),1,0) -> 1 | X12: =IF(AND(SCTR_Brokers[[#This Row],[Estado]]="FINALIZADO",SCTR_Brokers[[#This Row],[Plazo]]=LISTAS!$J$4),1,0) -> 0 | Y12: =IF(AND(SCTR_Brokers[[#This Row],[Estado]]<>"FINALIZADO",SCTR_Brokers[[#This Row],[Plazo]]=LISTAS!$J$4),1,0) -> 0 | Z12: =IF(SCTR_Brokers[[#This Row],[Fecha_Solic_Informe]]="",0,1) -> 0 | AA12: =IF(SCTR_Brokers[[#This Row],[Fecha_Informe]]="",0,1) -> 0 | AB12: =IF(AND(SCTR_Brokers[[#This Row],[Fecha_Solic_Informe]]<>"",SCTR_Brokers[[#This Row],[Fecha_Informe]]=""),1,0) -> 0 | AC12: =IF(AND(SCTR_Brokers[[#This Row],[Fecha_Solic_Informe]]<>"",SCTR_Brokers[[#This Row],[Fecha_Informe]]<>""),ROUND((SCTR_Brokers[[#This Row],[Fecha_Informe]]-SCTR_Brokers[[#This Row],[Fecha_Solic_Informe]])*24,1),"")
A13: AAQkADdkNThjNzFkLWM0ZmMtNDJhYS04MDVlLTIwNzE4ZDI1Mzg4YgAQAL3ITZJk9d9Fkya9zVOFO74= | C13: =IF(SCTR_Brokers[[#This Row],[FechaRecepcion]]="","",SCTR_Brokers[[#This Row],[ConversationId]]&"-"&TEXT(SCTR_Brokers[[#This Row],[FechaRecepcion]],"aaaammddhhmmss")) -> AAQkADdkNThjNzFkLWM0ZmMtNDJhYS04MDVlLTIwNzE4ZDI1Mzg4YgAQAL3ITZJk9d9Fkya9zVOFO74=-20260814104959 | D13: CAMBIO DE PROVEEDOR / SCTR SALUD / ASG NAVARRO VILLANUEVA MIKELA / CRUZ DEL SUR / MAPFRE | E13: HOWDEN | F13: 46248.451 | G13: 46248.468 | H13: rrodas@contacto.com.pe | I13: FINALIZADO | K13: SCTR SALUD | N13: =IF(SCTR_Brokers[[#This Row],[FechaRecepcion]]="","",IF(SCTR_Brokers[[#This Row],[Estado]]="FINALIZADO","",IF(SCTR_Brokers[[#This Row],[FechaUltimaRespuesta]]="","",_xlfn.LET(_xlpm.fer,LISTAS!$L$3:$L$100,_xlpm.ep,DATE(2000,1,1),_xlpm.ini,SCTR_Brokers[[#This Row],[FechaUltimaRespuesta]],_xlpm.fin,NOW(),_xlpm.dini,INT(_xlpm.ini),_xlpm.dfin,INT(_xlpm.fin),_xlpm.hini,9.5*NETWORKDAYS.INTL(_xlpm.ep,_xlpm.dini-1,"0000111",_xlpm.fer)+6*NETWORKDAYS.INTL(_xlpm.ep,_xlpm.dini-1,"1111011",_xlpm.fer)+IF(OR(WEEKDAY(_xlpm.dini,2)>5,COUNTIF(_xlpm.fer,_xlpm.dini)>0),0,MAX(0,MIN(_xlpm.ini-_xlpm.dini,IF(WEEKDAY(_xlpm.dini,2)=5,14/24,17.5/24))-8/24)*24),_xlpm.hfin,9.5*NETWORKDAYS.INTL(_xlpm.ep,_xlpm.dfin-1,"0000111",_xlpm.fer)+6*NETWORKDAYS.INTL(_xlpm.ep,_xlpm.dfin-1,"1111011",_xlpm.fer)+IF(OR(WEEKDAY(_xlpm.dfin,2)>5,COUNTIF(_xlpm.fer,_xlpm.dfin)>0),0,MAX(0,MIN(_xlpm.fin-_xlpm.dfin,IF(WEEKDAY(_xlpm.dfin,2)=5,14/24,17.5/24))-8/24)*24),ROUND(MAX(0,_xlpm.hfin-_xlpm.hini),1))))) | Q13: 46248.499 | R13: =IF(SCTR_Brokers[[#This Row],[FechaRecepcion]]="","",_xlfn.LET(_xlpm.fer,LISTAS!$L$3:$L$100,_xlpm.ep,DATE(2000,1,1),_xlpm.ini,SCTR_Brokers[[#This Row],[FechaRecepcion]],_xlpm.fin,IF(SCTR_Brokers[[#This Row],[Fecha_Cierre]]<>"",SCTR_Brokers[[#This Row],[Fecha_Cierre]],NOW()),_xlpm.dini,INT(_xlpm.ini),_xlpm.dfin,INT(_xlpm.fin),_xlpm.hini,9.5*NETWORKDAYS.INTL(_xlpm.ep,_xlpm.dini-1,"0000111",_xlpm.fer)+6*NETWORKDAYS.INTL(_xlpm.ep,_xlpm.dini-1,"1111011",_xlpm.fer)+IF(OR(WEEKDAY(_xlpm.dini,2)>5,COUNTIF(_xlpm.fer,_xlpm.dini)>0),0,MAX(0,MIN(_xlpm.ini-_xlpm.dini,IF(WEEKDAY(_xlpm.dini,2)=5,14/24,17.5/24))-8/24)*24),_xlpm.hfin,9.5*NETWORKDAYS.INTL(_xlpm.ep,_xlpm.dfin-1,"0000111",_xlpm.fer)+6*NETWORKDAYS.INTL(_xlpm.ep,_xlpm.dfin-1,"1111011",_xlpm.fer)+IF(OR(WEEKDAY(_xlpm.dfin,2)>5,COUNTIF(_xlpm.fer,_xlpm.dfin)>0),0,MAX(0,MIN(_xlpm.fin-_xlpm.dfin,IF(WEEKDAY(_xlpm.dfin,2)=5,14/24,17.5/24))-8/24)*24),_xlpm.hrs,IF(SCTR_Brokers[[#This Row],[Estado]]="FINALIZADO",MAX(0,_xlpm.hfin-_xlpm.hini),IF(SCTR_Brokers[[#This Row],[Horas_Transcurridas]]="",MAX(0,_xlpm.hfin-_xlpm.hini),SCTR_Brokers[[#This Row],[Horas_Transcurridas]])),IF(_xlpm.hrs<=LISTAS!$E$3,LISTAS!$J$3,LISTAS!$J$4))) -> Dentro | T13: =IF(SCTR_Brokers[[#This Row],[FechaRecepcion]]="","",TEXT(SCTR_Brokers[[#This Row],[FechaRecepcion]],"mmmm")&" "&YEAR(SCTR_Brokers[[#This Row],[FechaRecepcion]])) -> agosto 2026 | U13: =IF(SCTR_Brokers[[#This Row],[Estado]]="FINALIZADO",1,0) -> 1 | V13: =IF(SCTR_Brokers[[#This Row],[FechaRecepcion]]="","",IF(SCTR_Brokers[[#This Row],[Estado]]="FINALIZADO",0,1)) -> 0 | W13: =IF(AND(SCTR_Brokers[[#This Row],[Estado]]="FINALIZADO",SCTR_Brokers[[#This Row],[Plazo]]=LISTAS!$J$3),1,0) -> 1 | X13: =IF(AND(SCTR_Brokers[[#This Row],[Estado]]="FINALIZADO",SCTR_Brokers[[#This Row],[Plazo]]=LISTAS!$J$4),1,0) -> 0 | Y13: =IF(AND(SCTR_Brokers[[#This Row],[Estado]]<>"FINALIZADO",SCTR_Brokers[[#This Row],[Plazo]]=LISTAS!$J$4),1,0) -> 0 | Z13: =IF(SCTR_Brokers[[#This Row],[Fecha_Solic_Informe]]="",0,1) -> 0 | AA13: =IF(SCTR_Brokers[[#This Row],[Fecha_Informe]]="",0,1) -> 0 | AB13: =IF(AND(SCTR_Brokers[[#This Row],[Fecha_Solic_Informe]]<>"",SCTR_Brokers[[#This Row],[Fecha_Informe]]=""),1,0) -> 0 | AC13: =IF(AND(SCTR_Brokers[[#This Row],[Fecha_Solic_Informe]]<>"",SCTR_Brokers[[#This Row],[Fecha_Informe]]<>""),ROUND((SCTR_Brokers[[#This Row],[Fecha_Informe]]-SCTR_Brokers[[#This Row],[Fecha_Solic_Informe]])*24,1),"")
... A16: AAQkADdkNThjNzFkLWM0ZmMtNDJhYS04MDVlLTIwNzE4ZDI1Mzg4YgAQAD_wnXEnjrNOuaL_qkr7GmE= | C16: =IF(SCTR_Brokers[[#This Row],[FechaRecepcion]]="","",SCTR_Brokers[[#This Row],[ConversationId]]&"-"&TEXT(SCTR_Brokers[[#This Row],[FechaRecepcion]],"aaaammddhhmmss")) -> AAQkADdkNThjNzFkLWM0ZmMtNDJhYS04MDVlLTIwNzE4ZDI1Mzg4YgAQAD_wnXEnjrNOuaL_qkr7GmE=-20260814120034 | D16: RE: EVALUACIÓN POR PROCEDIMIENTO NO CUBIERTO/ SCTR SALUD/ ASG HUAMANTICO LAURA ROBERTO / CEMENTOS INKA / MAPFRE | E16: HOWDEN | F16: 46248.5 | G16: 46248.507 | H16: sctrsalud@mapfre.com.pe | I16: FINALIZADO | K16: SCTR SALUD | N16: =IF(SCTR_Brokers[[#This Row],[FechaRecepcion]]="","",IF(SCTR_Brokers[[#This Row],[Estado]]="FINALIZADO","",IF(SCTR_Brokers[[#This Row],[FechaUltimaRespuesta]]="","",_xlfn.LET(_xlpm.fer,LISTAS!$L$3:$L$100,_xlpm.ep,DATE(2000,1,1),_xlpm.ini,SCTR_Brokers[[#This Row],[FechaUltimaRespuesta]],_xlpm.fin,NOW(),_xlpm.dini,INT(_xlpm.ini),_xlpm.dfin,INT(_xlpm.fin),_xlpm.hini,9.5*NETWORKDAYS.INTL(_xlpm.ep,_xlpm.dini-1,"0000111",_xlpm.fer)+6*NETWORKDAYS.INTL(_xlpm.ep,_xlpm.dini-1,"1111011",_xlpm.fer)+IF(OR(WEEKDAY(_xlpm.dini,2)>5,COUNTIF(_xlpm.fer,_xlpm.dini)>0),0,MAX(0,MIN(_xlpm.ini-_xlpm.dini,IF(WEEKDAY(_xlpm.dini,2)=5,14/24,17.5/24))-8/24)*24),_xlpm.hfin,9.5*NETWORKDAYS.INTL(_xlpm.ep,_xlpm.dfin-1,"0000111",_xlpm.fer)+6*NETWORKDAYS.INTL(_xlpm.ep,_xlpm.dfin-1,"1111011",_xlpm.fer)+IF(OR(WEEKDAY(_xlpm.dfin,2)>5,COUNTIF(_xlpm.fer,_xlpm.dfin)>0),0,MAX(0,MIN(_xlpm.fin-_xlpm.dfin,IF(WEEKDAY(_xlpm.dfin,2)=5,14/24,17.5/24))-8/24)*24),ROUND(MAX(0,_xlpm.hfin-_xlpm.hini),1))))) | Q16: 46248.55 | R16: =IF(SCTR_Brokers[[#This Row],[FechaRecepcion]]="","",_xlfn.LET(_xlpm.fer,LISTAS!$L$3:$L$100,_xlpm.ep,DATE(2000,1,1),_xlpm.ini,SCTR_Brokers[[#This Row],[FechaRecepcion]],_xlpm.fin,IF(SCTR_Brokers[[#This Row],[Fecha_Cierre]]<>"",SCTR_Brokers[[#This Row],[Fecha_Cierre]],NOW()),_xlpm.dini,INT(_xlpm.ini),_xlpm.dfin,INT(_xlpm.fin),_xlpm.hini,9.5*NETWORKDAYS.INTL(_xlpm.ep,_xlpm.dini-1,"0000111",_xlpm.fer)+6*NETWORKDAYS.INTL(_xlpm.ep,_xlpm.dini-1,"1111011",_xlpm.fer)+IF(OR(WEEKDAY(_xlpm.dini,2)>5,COUNTIF(_xlpm.fer,_xlpm.dini)>0),0,MAX(0,MIN(_xlpm.ini-_xlpm.dini,IF(WEEKDAY(_xlpm.dini,2)=5,14/24,17.5/24))-8/24)*24),_xlpm.hfin,9.5*NETWORKDAYS.INTL(_xlpm.ep,_xlpm.dfin-1,"0000111",_xlpm.fer)+6*NETWORKDAYS.INTL(_xlpm.ep,_xlpm.dfin-1,"1111011",_xlpm.fer)+IF(OR(WEEKDAY(_xlpm.dfin,2)>5,COUNTIF(_xlpm.fer,_xlpm.dfin)>0),0,MAX(0,MIN(_xlpm.fin-_xlpm.dfin,IF(WEEKDAY(_xlpm.dfin,2)=5,14/24,17.5/24))-8/24)*24),_xlpm.hrs,IF(SCTR_Brokers[[#This Row],[Estado]]="FINALIZADO",MAX(0,_xlpm.hfin-_xlpm.hini),IF(SCTR_Brokers[[#This Row],[Horas_Transcurridas]]="",MAX(0,_xlpm.hfin-_xlpm.hini),SCTR_Brokers[[#This Row],[Horas_Transcurridas]])),IF(_xlpm.hrs<=LISTAS!$E$3,LISTAS!$J$3,LISTAS!$J$4))) -> Dentro | T16: =IF(SCTR_Brokers[[#This Row],[FechaRecepcion]]="","",TEXT(SCTR_Brokers[[#This Row],[FechaRecepcion]],"mmmm")&" "&YEAR(SCTR_Brokers[[#This Row],[FechaRecepcion]])) -> agosto 2026 | U16: =IF(SCTR_Brokers[[#This Row],[Estado]]="FINALIZADO",1,0) -> 1 | V16: =IF(SCTR_Brokers[[#This Row],[FechaRecepcion]]="","",IF(SCTR_Brokers[[#This Row],[Estado]]="FINALIZADO",0,1)) -> 0 | W16: =IF(AND(SCTR_Brokers[[#This Row],[Estado]]="FINALIZADO",SCTR_Brokers[[#This Row],[Plazo]]=LISTAS!$J$3),1,0) -> 1 | X16: =IF(AND(SCTR_Brokers[[#This Row],[Estado]]="FINALIZADO",SCTR_Brokers[[#This Row],[Plazo]]=LISTAS!$J$4),1,0) -> 0 | Y16: =IF(AND(SCTR_Brokers[[#This Row],[Estado]]<>"FINALIZADO",SCTR_Brokers[[#This Row],[Plazo]]=LISTAS!$J$4),1,0) -> 0 | Z16: =IF(SCTR_Brokers[[#This Row],[Fecha_Solic_Informe]]="",0,1) -> 0 | AA16: =IF(SCTR_Brokers[[#This Row],[Fecha_Informe]]="",0,1) -> 0 | AB16: =IF(AND(SCTR_Brokers[[#This Row],[Fecha_Solic_Informe]]<>"",SCTR_Brokers[[#This Row],[Fecha_Informe]]=""),1,0) -> 0 | AC16: =IF(AND(SCTR_Brokers[[#This Row],[Fecha_Solic_Informe]]<>"",SCTR_Brokers[[#This Row],[Fecha_Informe]]<>""),ROUND((SCTR_Brokers[[#This Row],[Fecha_Informe]]-SCTR_Brokers[[#This Row],[Fecha_Solic_Informe]])*24,1),"")
A17: AAQkADdkNThjNzFkLWM0ZmMtNDJhYS04MDVlLTIwNzE4ZDI1Mzg4YgAQAN8nmHl1gsBAj4k02S1J6vc= | C17: =IF(SCTR_Brokers[[#This Row],[FechaRecepcion]]="","",SCTR_Brokers[[#This Row],[ConversationId]]&"-"&TEXT(SCTR_Brokers[[#This Row],[FechaRecepcion]],"aaaammddhhmmss")) -> AAQkADdkNThjNzFkLWM0ZmMtNDJhYS04MDVlLTIwNzE4ZDI1Mzg4YgAQAN8nmHl1gsBAj4k02S1J6vc=-20260814122801 | D17: PESQUERA DIAMANTE : Bloqueo Caudal: CAYLLAHUA FLORES MAYCOL | E17: ARTHUR GALLAGHER | F17: 46248.519 | G17: 46248.55 | H17: sctrsalud@mapfre.com.pe | I17: FINALIZADO | K17: SCTR SALUD | L17: Buenos días:_x000D_ _x000D_ Estimados, favor su apoyo con la evaluación de lo solicitado en el adjunto._x000D_ _x000D_ _x000D_ Saludos,_x000D_ _x000D_ _x000D_ _x000D_ Alicia Sancca Medina_x000D_ _x000D_ Área de SCTR Salud_x000D_ _x000D_ Siniestros y Prestaciones_x000D_ _x000D_ Mapfre Perú_x000D_ _x000D_ Av. Armendáriz 345, Miraflores._x000D_ _x000D_ _x000D_ _x000D_ #CuidamosLoQu | N17: =IF(SCTR_Brokers[[#This Row],[FechaRecepcion]]="","",IF(SCTR_Brokers[[#This Row],[Estado]]="FINALIZADO","",IF(SCTR_Brokers[[#This Row],[FechaUltimaRespuesta]]="","",_xlfn.LET(_xlpm.fer,LISTAS!$L$3:$L$100,_xlpm.ep,DATE(2000,1,1),_xlpm.ini,SCTR_Brokers[[#This Row],[FechaUltimaRespuesta]],_xlpm.fin,NOW(),_xlpm.dini,INT(_xlpm.ini),_xlpm.dfin,INT(_xlpm.fin),_xlpm.hini,9.5*NETWORKDAYS.INTL(_xlpm.ep,_xlpm.dini-1,"0000111",_xlpm.fer)+6*NETWORKDAYS.INTL(_xlpm.ep,_xlpm.dini-1,"1111011",_xlpm.fer)+IF(OR(WEEKDAY(_xlpm.dini,2)>5,COUNTIF(_xlpm.fer,_xlpm.dini)>0),0,MAX(0,MIN(_xlpm.ini-_xlpm.dini,IF(WEEKDAY(_xlpm.dini,2)=5,14/24,17.5/24))-8/24)*24),_xlpm.hfin,9.5*NETWORKDAYS.INTL(_xlpm.ep,_xlpm.dfin-1,"0000111",_xlpm.fer)+6*NETWORKDAYS.INTL(_xlpm.ep,_xlpm.dfin-1,"1111011",_xlpm.fer)+IF(OR(WEEKDAY(_xlpm.dfin,2)>5,COUNTIF(_xlpm.fer,_xlpm.dfin)>0),0,MAX(0,MIN(_xlpm.fin-_xlpm.dfin,IF(WEEKDAY(_xlpm.dfin,2)=5,14/24,17.5/24))-8/24)*24),ROUND(MAX(0,_xlpm.hfin-_xlpm.hini),1))))) | O17: 46248.534 | P17: 46248.546 | Q17: 46248.55 | R17: =IF(SCTR_Brokers[[#This Row],[FechaRecepcion]]="","",_xlfn.LET(_xlpm.fer,LISTAS!$L$3:$L$100,_xlpm.ep,DATE(2000,1,1),_xlpm.ini,SCTR_Brokers[[#This Row],[FechaRecepcion]],_xlpm.fin,IF(SCTR_Brokers[[#This Row],[Fecha_Cierre]]<>"",SCTR_Brokers[[#This Row],[Fecha_Cierre]],NOW()),_xlpm.dini,INT(_xlpm.ini),_xlpm.dfin,INT(_xlpm.fin),_xlpm.hini,9.5*NETWORKDAYS.INTL(_xlpm.ep,_xlpm.dini-1,"0000111",_xlpm.fer)+6*NETWORKDAYS.INTL(_xlpm.ep,_xlpm.dini-1,"1111011",_xlpm.fer)+IF(OR(WEEKDAY(_xlpm.dini,2)>5,COUNTIF(_xlpm.fer,_xlpm.dini)>0),0,MAX(0,MIN(_xlpm.ini-_xlpm.dini,IF(WEEKDAY(_xlpm.dini,2)=5,14/24,17.5/24))-8/24)*24),_xlpm.hfin,9.5*NETWORKDAYS.INTL(_xlpm.ep,_xlpm.dfin-1,"0000111",_xlpm.fer)+6*NETWORKDAYS.INTL(_xlpm.ep,_xlpm.dfin-1,"1111011",_xlpm.fer)+IF(OR(WEEKDAY(_xlpm.dfin,2)>5,COUNTIF(_xlpm.fer,_xlpm.dfin)>0),0,MAX(0,MIN(_xlpm.fin-_xlpm.dfin,IF(WEEKDAY(_xlpm.dfin,2)=5,14/24,17.5/24))-8/24)*24),_xlpm.hrs,IF(SCTR_Brokers[[#This Row],[Estado]]="FINALIZADO",MAX(0,_xlpm.hfin-_xlpm.hini),IF(SCTR_Brokers[[#This Row],[Horas_Transcurridas]]="",MAX(0,_xlpm.hfin-_xlpm.hini),SCTR_Brokers[[#This Row],[Horas_Transcurridas]])),IF(_xlpm.hrs<=LISTAS!$E$3,LISTAS!$J$3,LISTAS!$J$4))) -> Dentro | T17: =IF(SCTR_Brokers[[#This Row],[FechaRecepcion]]="","",TEXT(SCTR_Brokers[[#This Row],[FechaRecepcion]],"mmmm")&" "&YEAR(SCTR_Brokers[[#This Row],[FechaRecepcion]])) -> agosto 2026 | U17: =IF(SCTR_Brokers[[#This Row],[Estado]]="FINALIZADO",1,0) -> 1 | V17: =IF(SCTR_Brokers[[#This Row],[FechaRecepcion]]="","",IF(SCTR_Brokers[[#This Row],[Estado]]="FINALIZADO",0,1)) -> 0 | W17: =IF(AND(SCTR_Brokers[[#This Row],[Estado]]="FINALIZADO",SCTR_Brokers[[#This Row],[Plazo]]=LISTAS!$J$3),1,0) -> 1 | X17: =IF(AND(SCTR_Brokers[[#This Row],[Estado]]="FINALIZADO",SCTR_Brokers[[#This Row],[Plazo]]=LISTAS!$J$4),1,0) -> 0 | Y17: =IF(AND(SCTR_Brokers[[#This Row],[Estado]]<>"FINALIZADO",SCTR_Brokers[[#This Row],[Plazo]]=LISTAS!$J$4),1,0) -> 0 | Z17: =IF(SCTR_Brokers[[#This Row],[Fecha_Solic_Informe]]="",0,1) -> 1 | AA17: =IF(SCTR_Brokers[[#This Row],[Fecha_Informe]]="",0,1) -> 1 | AB17: =IF(AND(SCTR_Brokers[[#This Row],[Fecha_Solic_Informe]]<>"",SCTR_Brokers[[#This Row],[Fecha_Informe]]=""),1,0) -> 0 | AC17: =IF(AND(SCTR_Brokers[[#This Row],[Fecha_Solic_Informe]]<>"",SCTR_Brokers[[#This Row],[Fecha_Informe]]<>""),ROUND((SCTR_Brokers[[#This Row],[Fecha_Informe]]-SCTR_Brokers[[#This Row],[Fecha_Solic_Informe]])*24,1),"") -> 0.3
